Workbook

Sheet 测试结果
B2: 测试结果汇总
B3: 序号 | C3: 模块 | D3: 测试结果 | E3: S类问题数量 | F3: S类问题明细 | G3: A类问题数量 | H3: A类问题明细 | I3: 备注
B4: 1
B5: 2
B6: 3
B7: 4
B8: 5
B9: 6
B10: 7
B11: 8
B12: 9
B13: 10
B14: 11
B15: 12
... B32: 29

Sheet 数据统计
B2: 测试用例数据统计
B3: 统计结果 | C3: 模块 | F3: 总用例 | G3: 已执行用例数 | H3: passed | I3: failed | J3: blocked | K3: NA | L3: 通过率
C4: 冒烟测试用例 | F4: =冒烟测试用例!B1 -> 34 | G4: =SUM(H4:K4) -> 0 | H4: =冒烟测试用例!B2 -> 0 | I4: =冒烟测试用例!B3 -> 0 | J4: =冒烟测试用例!B4 -> 0 | K4: =冒烟测试用例!B5 -> 0 | L4: =H4/(H4+I4+J4)*100% -> #DIV/0!
C5: AI主页 | F5: =AI主页!B1 -> 116 | G5: =SUM(H5:K5) -> 0 | H5: =AI主页!B2 -> 0 | I5: =AI主页!B3 -> 0 | J5: =AI主页!B4 -> 0 | K5: =AI主页!B5 -> 0 | L5: =H5/(H5+I5+J5)*100% -> #DIV/0!
C6: 娱乐主页&QQ音乐&喜马拉雅 | F6: ='娱乐主页&QQ音乐&喜马拉雅'!B1 -> 145 | G6: =SUM(H6:K6) -> 0 | H6: ='娱乐主页&QQ音乐&喜马拉雅'!B2 -> 0 | I6: ='娱乐主页&QQ音乐&喜马拉雅'!B3 -> 0 | J6: ='娱乐主页&QQ音乐&喜马拉雅'!B4 -> 0 | K6: ='娱乐主页&QQ音乐&喜马拉雅'!B5 -> 0 | L6: =H6/(H6+I6+J6)*100% -> #DIV/0!
C7: 本地&蓝牙音乐 | F7: ='本地&蓝牙音乐'!B1 -> 148 | G7: =SUM(H7:K7) -> 0 | H7: ='本地&蓝牙音乐'!B2 -> 0 | I7: ='本地&蓝牙音乐'!B3 -> 0 | J7: ='本地&蓝牙音乐'!B4 -> 0 | K7: ='本地&蓝牙音乐'!B5 -> 0 | L7: =H7/(H7+I7+J7)*100% -> #DIV/0!
C8: 车主页 | F8: =车主页!B1 -> 30 | G8: =SUM(H8:K8) -> 0 | H8: =车主页!B2 -> 0 | I8: =车主页!B3 -> 0 | J8: =车主页!B4 -> 0 | K8: =车主页!B5 -> 0 | L8: =H8/(H8+I8+J8)*100% -> #DIV/0!
C9: 导航主页 | F9: =导航主页!B1 -> 84 | G9: =SUM(H9:K9) -> 0 | H9: =导航主页!B2 -> 0 | I9: =导航主页!B3 -> 0 | J9: =导航主页!B4 -> 0 | K9: =导航主页!B5 -> 0 | L9: =H9/(H9+I9+J9)*100% -> #DIV/0!
C10: 高德地图 | F10: =高德地图!B1 -> 191 | G10: =SUM(H10:K10) -> 0 | H10: =高德地图!B2 -> 0 | I10: =高德地图!B3 -> 0 | J10: =高德地图!B4 -> 0 | K10: =高德地图!B5 -> 0 | L10: =H10/(H10+I10+J10)*100% -> #DIV/0!
C11: 状态栏 | F11: ='状态栏(底部状态栏)'!B1 -> 66 | G11: =SUM(H11:K11) -> 0 | H11: ='状态栏(底部状态栏)'!B2 -> 0 | I11: ='状态栏(底部状态栏)'!B3 -> 0 | J11: ='状态栏(底部状态栏)'!B4 -> 0 | K11: ='状态栏(底部状态栏)'!B5 -> 0 | L11: =H11/(H11+I11+J11)*100% -> #DIV/0!
C12: 文件管理 | F12: =文件管理!B1 -> 144 | G12: =SUM(H12:K12) -> 0 | H12: =文件管理!B2 -> 0 | I12: =文件管理!B3 -> 0 | J12: =文件管理!B4 -> 0 | K12: =文件管理!B5 -> 0 | L12: =H12/(H12+I12+J12)*100% -> #DIV/0!
C13: 自检APP | F13: =自检APP!B1 -> 24 | G13: =SUM(H13:K13) -> 0 | H13: =自检APP!B2 -> 0 | I13: =自检APP!B3 -> 0 | J13: =自检APP!B4 -> 0 | K13: =自检APP!B5 -> 0 | L13: =H13/(H13+I13+J13)*100% -> #DIV/0!
C14: 蓝牙电话 | F14: =蓝牙电话!B1 -> 191 | G14: =SUM(H14:K14) -> 0 | H14: =蓝牙电话!B2 -> 0 | I14: =蓝牙电话!B3 -> 0 | J14: =蓝牙电话!B4 -> 0 | K14: =蓝牙电话!B5 -> 0 | L14: =H14/(H14+I14+J14)*100% -> #DIV/0!
C15: 鉴权 | F15: =鉴权!B1 -> 26 | G15: =SUM(H15:K15) -> 0 | H15: =鉴权!B2 -> 0 | I15: =鉴权!B3 -> 0 | J15: =鉴权!B4 -> 0 | K15: =鉴权!B5 -> 0 | L15: =H15/(H15+I15+J15)*100% -> #DIV/0!
C16: 双屏互动 | F16: =双屏互动!B1 -> 196 | G16: =SUM(H16:K16) -> 0 | H16: =双屏互动!B2 -> 0 | I16: =双屏互动!B3 -> 0 | J16: =双屏互动!B4 -> 0 | K16: =双屏互动!B5 -> 0 | L16: =H16/(H16+I16+J16)*100% -> #DIV/0!
C17: 系统设置 | F17: =系统设置!B1 -> 192 | G17: =SUM(H17:K17) -> 0 | H17: =系统设置!B2 -> 0 | I17: =系统设置!B3 -> 0 | J17: =系统设置!B4 -> 0 | K17: =系统设置!B5 -> 0 | L17: =H17/(H17+I17+J17)*100% -> #DIV/0!
C18: 智能提示 | F18: =智能提示!B1 -> 57 | G18: =SUM(H18:K18) -> 0 | H18: =智能提示!B2 -> 0 | I18: =智能提示!B3 -> 0 | J18: =智能提示!B4 -> 0 | K18: =智能提示!B5 -> 0 | L18: =H18/(H18+I18+J18)*100% -> #DIV/0!
C19: 智能推荐 | F19: =智能推荐!B1 -> 55 | G19: =SUM(H19:K19) -> 0 | H19: =智能推荐!B2 -> 0 | I19: =智能推荐!B3 -> 0 | J19: =智能推荐!B4 -> 0 | K19: =智能推荐!B5 -> 0 | L19: =H19/(H19+I19+J19)*100% -> #DIV/0!
C20: ACC&IACC推荐 | F20: ='ACC&IACC推荐'!B1 -> 124 | G20: =SUM(H20:K20) -> 0 | H20: ='ACC&IACC推荐'!B2 -> 0 | I20: ='ACC&IACC推荐'!B3 -> 0 | J20: ='ACC&IACC推荐'!B4 -> 0 | K20: ='ACC&IACC推荐'!B5 -> 0 | L20: =H20/(H20+I20+J20)*100% -> #DIV/0!
C21: 车辆设置 | F21: 534 | G21: 0 | H21: 0 | I21: 0 | J21: 0 | K21: 0 | L21: =H21/(H21+I21+J21)*100% -> #DIV/0!
C22: 全景影像 | F22: =全景影像!B1 -> 173 | G22: =SUM(H22:K22) -> 0 | H22: =全景影像!B2 -> 0 | I22: =全景影像!B3 -> 0 | J22: =全景影像!B4 -> 0 | K22: =全景影像!B5 -> 0 | L22: =H22/(H22+I22+J22)*100% -> #DIV/0!
C23: 雷达动态显示 | F23: =雷达动态显示!B1 -> 91 | G23: =SUM(H23:K23) -> 0 | H23: =雷达动态显示!B2 -> 0 | I23: =雷达动态显示!B3 -> 0 | J23: =雷达动态显示!B4 -> 0 | K23: =雷达动态显示!B5 -> 0 | L23: =H23/(H23+I23+J23)*100% -> #DIV/0!
C24: 升级 | F24: =升级!B1 -> 48 | G24: =SUM(H24:K24) -> 0 | H24: =升级!B2 -> 0 | I24: =升级!B3 -> 0 | J24: =升级!B4 -> 0 | K24: =升级!B5 -> 0 | L24: =H24/(H24+I24+J24)*100% -> #DIV/0!
C25: 爱奇艺 | F25: =爱奇艺!B1 -> 79 | G25: =SUM(H25:K25) -> 0 | H25: =爱奇艺!B2 -> 0 | I25: =爱奇艺!B3 -> 0 | J25: =爱奇艺!B4 -> 0 | K25: =爱奇艺!B5 -> 0 | L25: =H25/(H25+I25+J25)*100% -> #DIV/0!
C26: 长安品牌电台 | F26: =长安品牌电台!B1 -> 9 | G26: =SUM(H26:K26) -> 0 | H26: =长安品牌电台!B2 -> 0 | I26: =长安品牌电台!B3 -> 0 | J26: =长安品牌电台!B4 -> 0 | K26: =长安品牌电台!B5 -> 0 | L26: =H26/(H26+I26+J26)*100% -> #DIV/0!
C27: 空调APP | F27: =空调APP!B1 -> 83 | G27: =SUM(H27:K27) -> 0 | H27: =空调APP!B2 -> 0 | I27: =空调APP!B3 -> 0 | J27: =空调APP!B4 -> 0 | K27: =空调APP!B5 -> 0 | L27: =H27/(H27+I27+J27)*100% -> #DIV/0!
C28: 行车记录仪 | F28: =行车记录仪!B1 -> 299 | G28: =SUM(H28:K28) -> 0 | H28: =行车记录仪!B2 -> 0 | I28: =行车记录仪!B3 -> 0 | J28: =行车记录仪!B4 -> 0 | K28: =行车记录仪!B5 -> 0 | L28: =H28/(H28+I28+J28)*100% -> #DIV/0!
C29: 智慧ID | F29: =智慧ID!B1 -> 83 | G29: =SUM(H29:K29) -> 0 | H29: =智慧ID!B2 -> 0 | I29: =智慧ID!B3 -> 0 | J29: =智慧ID!B4 -> 0 | K29: =智慧ID!B5 -> 0 | L29: =H29/(H29+I29+J29)*100% -> #DIV/0!
C30: 电源管理 | F30: =电源管理!B1 -> 424 | G30: =SUM(H30:K30) -> 0 | H30: =电源管理!B2 -> 0 | I30: =电源管理!B3 -> 0 | J30: =电源管理!B4 -> 0 | K30: =电源管理!B5 -> 0 | L30: =H30/(H30+I30+J30)*100% -> #DIV/0!
C31: 4G专项 | F31: ='4G专项'!B1 -> 723 | G31: =SUM(H31:K31) -> 0 | H31: ='4G专项'!B2 -> 0 | I31: ='4G专项'!B3 -> 0 | J31: ='4G专项'!B4 -> 0 | K31: ='4G专项'!B5 -> 0 | L31: =H31/(H31+I31+J31)*100% -> #DIV/0!
C32: 语音专项 | F32: ='语音专项(在线)'!B1 -> 341 | G32: =SUM(H32:K32) -> 73 | H32: ='语音专项(在线)'!B2 -> 9 | I32: ='语音专项(在线)'!B3 -> 16 | J32: ='语音专项(在线)'!B4 -> 22 | K32: ='语音专项(在线)'!B5 -> 26 | L32: =H32/(H32+I32+J32)*100% -> 0.19148936
C33: 音源切换 | F33: =音源切换!B1 -> 981 | G33: =SUM(H33:K33) -> 0 | H33: =音源切换!B2 -> 0 | I33: =音源切换!B3 -> 0 | J33: =音源切换!B4 -> 0 | K33: =音源切换!B5 -> 0 | L33: =H33/(H33+I33+J33)*100% -> #DIV/0!
C34: 交互测试 | F34: =交互测试!B1 -> 236 | G34: =SUM(H34:K34) -> 0 | H34: =交互测试!B2 -> 0 | I34: =交互测试!B3 -> 0 | J34: =交互测试!B4 -> 0 | K34: =交互测试!B5 -> 0 | L34: =H34/(H34+I34+J34)*100% -> #DIV/0!
C35: 稳定性测试 | F35: =稳定性测试!B1 -> 10 | G35: =SUM(H35:K35) -> 0 | H35: =稳定性测试!B2 -> 0 | I35: =稳定性测试!B3 -> 0 | J35: =稳定性测试!B4 -> 0 | K35: =稳定性测试!B5 -> 0 | L35: =H35/(H35+I35+J35)*100% -> #DIV/0!
C36: 压力测试 | F36: =压力测试!B1 -> 7 | G36: =SUM(H36:K36) -> 0 | H36: =压力测试!B2 -> 0 | I36: =压力测试!B3 -> 0 | J36: =压力测试!B4 -> 0 | K36: =压力测试!B5 -> 0 | L36: =H36/(H36+I36+J36)*100% -> #DIV/0!
C37: 兼容性测试 | F37: =兼容性测试!B1 -> 25 | G37: =SUM(H37:K37) -> 0 | H37: =兼容性测试!B2 -> 0 | I37: =兼容性测试!B3 -> 0 | J37: =兼容性测试!B4 -> 0 | K37: =兼容性测试!B5 -> 0 | L37: =H37/(H37+I37+J37)*100% -> #DIV/0!
C38: 总计 | F38: =SUM(F4:F37) -> 5969 | G38: =SUM(G4:G37) -> 73 | H38: =SUM(H4:H37) -> 9 | I38: =SUM(I4:I37) -> 16 | J38: =SUM(J4:J37) -> 22 | K38: =SUM(K4:K37) -> 26 | L38: =H38/(H38+I38+J38)*100% -> 0.19148936
C39: 通过率=passed/(passed+failed+blocked)*100%

Sheet Bug严重等级定义
A1: Bug严重等级定义
A2: 序号 | B2: 级别 | C2: 定义 | D2: 详细描述 | E2: 举例 | F2: 备注
A3: 1 | B3: S | C3: 必现性及大概率（1/100及以上)致命问题，不能用于量产及销售 | D3: 1、可导致驾驶人生命财产安全隐患的问题 | E3: 未做高压，低压，反接短路等保护，容易引发电路起火； 带机芯车机，按出碟后，碟片飞出来等；
D4: 2、违反国家法律法规、行业认证、客户规格要求及标准 | E4: 侵权设计，外观尺寸及设计不符合客户规范； 违背DV/EMC实验标准，导致硬件需要整改；
D5: 3、主界面APP功能（包含必须支持的第三方软件）及日常使用功能无法实现 | E5: 主界面app应用使用不了； 方控、面板按键、倒车无法使用； carplay、carlife无法使用；
D6: 4、常规操作导致系统奔溃 | E6: 死机，黑屏，闪屏，频繁重启，长时间卡屏
D7: 5、主要参数异常导致的直观显示问题 | E7: 屏幕输出出现大范围噪点，倒车影像/全景显示异常； 花屏、闪屏；
A8: 2 | B8: A | C8: 严重影响用户体验，导致用户退货或者阻碍产品发行，中等概率（1/100-1/1000）基本功能实现异常 | D8: 1、主界面APP子菜单功能（包含必须支持的第三方软件）无法实现，日常使用功能存在较大缺陷 | E8: 收音机无法搜索电台； 界面软按键不响应； 倒车闪屏； 按键异响等
D9: 2、UI,UE与设计标准出现较大差异 | E9: 界面布局不匹配，缺少或多余框架
D10: 3、软件实现逻辑引发的功能实现错误 | E10: 基本模块交互时的优先级（倒车，来电，音源输入，输出优先级等）； 记忆逻辑不能实现； 来电后混音； 多媒体叠音输出；
D11: 4、系统性能不满足要求 | E11: 车机休眠后，暗电流过高； 开机时间太长>20s； 倒车响应时间太长>4s；
D12: 5、偶发基本功能缺陷及系统奔溃问题 | E12: 偶发（1/100-1/1000）程序闪退； 长时间压力导致死机，黑屏，闪屏，重启，卡屏等 偶发升级时校验失败，数据灌装异常，需重启解决；
A13: 3 | B13: B | C13: 用户体验影响较差，容易造成批次量问题或者有较大可能被客户考核的问题，低概率（1/1000以下)基本功能实现异常 | D13: 1、主界面APP子菜单功能（包含必须支持的第三方软件）使用缺陷，日常使用功能存在轻微缺陷 | E13: 收音机搜完电台后无法自动收藏； 按键响应明显延时或不灵敏；
D14: 2、UI,UE与设计标准出现较小差异 | E14: 弹框风格不一致； 中英文切换后无转化；
D15: 3、软件实现逻辑引发的功能缺陷 | E15: 导航音源输出时，其他多媒体音源无衰减；
D16: 4、低概率基本功能缺陷及系统奔溃问题 | E16: 偶发（1/1000以下)程序闪退； 测试过程中低概率出现死机，黑屏，闪屏，重启，卡屏等
A17: 4 | B17: C | C17: 用户体验影响小，基本不影响正常使用，客户不容易或者很难发现的问题 | D17: 1、基本功能体验问题 | E17: 用户使用体念改善问题
D18: 2、UI,UE与设计标准出现轻微差异 | E18: 各级UI颜色深浅有细微差别； 字体不一致； 弹框显示文本位置未统一、信息显示不完全； 中英文切换后转化不完全等
D19: 3、建议性修改问题，PRD没需求，测试人员自己新的想法需求 | E19: 多媒体图片不支持文件夹显示（PRD不做文件夹显示要求）； 文件管理导入相同文件无系统提示等
D20: 4、PRD文档定义不清晰问题 | E20: 有的开关无按键音（按键音开关本身）

Sheet 冒烟测试用例
A1: 总用例 | B1: 34 | C1: XXX零部件测试冒烟测试用例
A2: passed | B2: =COUNTIF(J:J,"=passed") -> 0
A3: failed | B3: =COUNTIF(J:J,"=failed") -> 0
A4: blocked | B4: =COUNTIF(J:J,"=blocked") -> 0
A5: N/A | B5: =COUNTIF(J:J,"=N/A") -> 0
A6: 项目名称：CD569 | C6: 版本: | E6: 编制: | G6: 测试人员: | I6: 测试日期:
A7: 用例序号 | B7: 所属模块 | C7: 相关需求 | D7: 用例标题 | E7: 前置条件 | F7: 步骤 | G7: 预期 | H7: 优先级 | I7: 用例执行方式 | J7: 用例执行结果 | K7: DTM缺陷号
A8: 1 | B8: 4G | D8: TBOX登录后台 | E8: tbox唤醒 | F8: 1.启动车机，查看tsp上报信息 | G8: 1.在Kibana系统查询对应的车机TUID是否有上传tsp收到sid=5，mid=200的登录信息 | H8: 1 | I8: 台架
A9: 2 | B9: 4G | D9: 4G公网联通基本功能 | E9: 1.车机完成实名认证，tbox唤醒； | F9: 1.启动车机，播放在线音乐； | G9: 1.在线音乐可以正常播放； | H9: 1 | I9: 台架
A10: 3 | B10: 本地音乐&蓝牙音乐 | C10: I206本地音乐需求规格说明书-V1.3—3.1.2 USB | D10: S—接有音频文件的U盘 | E10: 车机已上电 | F10: 1.车机处于主界面 2.接有音频文件的U盘 | G10: 1.切换到 USB 音乐源并自动播放第一个识别出来的音频文 件 | H10: 1 | I10: 台架
A11: 4 | B11: 本地音乐&蓝牙音乐 | C11: I206本地音乐需求规格说明书-V1.3—3.1.3 蓝牙 | D11: S—蓝牙已连接,音源选择蓝牙,播放音乐 | E11: 蓝牙已连接 | F11: 1.蓝牙连接后播放音乐 | G11: 1.蓝牙音乐正常播放 | H11: 1 | I11: 台架
A12: 5 | B12: 本地音乐&蓝牙音乐 | C12: I206本地音乐需求规格说明书-V1.3—3.2 播放控制 | D12: F—点击“播放/暂停” | E12: 车机已上电 | F12: 1.播放USB音乐，然后点击“播放/暂停”； 2.切换播放蓝牙音乐，然后点击“播放/暂停”； | G12: 1-2.可以正常暂停/播放 | H12: 1 | I12: 台架
A13: 6 | B13: 本地音乐&蓝牙音乐 | C13: I206本地音乐需求规格说明书-V1.3—3.2 播放控制 | D13: F—暂停中点击“上/下一曲” | E13: 车机已上电 | F13: 1.播放USB音乐，点击“上/下一曲”； 2.切换播放蓝牙音乐，点击“上/下一曲”； | G13: 1-2.音乐可以正常上/下一曲切换； | H13: 1 | I13: 台架
A14: 7 | B14: 导航主页 | C14: 无 | D14: F-线路规划界面，可点击开始导航进行导航 | E14: 路线规划界面 | F14: 1. 点击开始导航按钮 | G14: 1. 进行导航 | H14: 1 | I14: 台架
A15: 8 | B15: 电源管理 | C15: I261电源管理需求规格说明书-V1.4_1.1电源状态定义 | D15: ACC ON/OFF状态切换 | E15: 1.THU处于ACC ON状态 2.插入有音视频资源的U盘 | F15: 1.将U盘中的文件拷贝1个到车机存储，然后将电源状态由ACC ON切换为ACC OFF 2.再将电源状态由ACC OFF 切换到ACC ON，检查拷贝的文件内容 | G15: 1.拷贝文件成功，切到ACC OFF后系统提示进入延时工作模式； 2.切到ACC ON后，HU唤醒系统脱离待机状态进入全工作状态，检查之前拷贝的文件正常； | H15: 1 | I15: 台架
A16: 9 | B16: 电源管理 | D16: 暗电流测试 | E16: 1.THU处于ACC OFF档 | F16: 1.通过万用表串联接到B+和GND端，查看流过的暗电流； | G16: 1.暗电流≤5mA | H16: 1 | I16: 台架
A17: 10 | B17: 方控-Mode | C17: I231方向盘键操控响应需求规格说明书-V0.7.pdf/3.7 音源切换（ I231.07.00.00 ） | D17: F-音源切换 | E17: 1.当前播放蓝牙音乐 | F17: 1.仿真发送ID=38A GW_MFS_Mode_switch=0x1，循环周期40ms； | G17: 1. 按“蓝牙音乐-在线音乐-USB音乐-本地音乐-广播电台（FM/AM）-在线节目”播放源循环切换，并播放对应音源上一次记忆的音乐。HU界面同步匹配音源 | H17: 1 | I17: 仿真
A18: 11 | B18: 方控SEEK- | C18: I231方向盘键操控响应需求规格说明书-V0.7.pdf/3.2 SEEK- （I231.02.00.00 ） | D18: F-SEEK-_独立按键_播放USB音乐_短按 | E18: 1.当前播放USB音乐 | F18: 1.仿真发送ID=38A GW_MFS_SeekReduce_switch=0x1，循环周期40ms； | G18: 1. 播放上一曲，HU 展示上一曲的相应界面 | H18: 1 | I18: 仿真
A19: 12 | B19: 方控SEEK+ | C19: I231方向盘键操控响应需求规格说明书-V0.7.pdf/3.1 SEEK+ （I231.01.00.00 ） | D19: F-SEEK+_独立按键_播放USB音乐_短按 | E19: 1.当前播放USB音乐 | F19: 1.仿真发送ID=38A GW_MFS_SeekPlus_switch=0x1，循环周期40ms； | G19: 1. 播放下一曲，HU 展示下一曲的相应界面 | H19: 1 | I19: 仿真
A20: 13 | B20: 工程模式 | D20: F-工模U盘导日志基本功能 | E20: 1.工模可以进入； | F20: 1.进入工模(进入工模方式找项目开发确认)，验证U盘导log是否可以导出； | G20: 1.可以成功导出U盘log； | H20: 1 | I20: 台架
A21: 14 | B21: 空调 | C21: 空调控制需求规格说明书V1.7 手动空气净化及提示I230.01.04.00 | D21: 点击空调app打开空气净化 | E21: 1.电源处于ON档， HU 处于开机状态 | F21: 1. 进入空调APP，点击空气净化图标开启净化 | G21: 1.输出开启离子发生器HU_IonizerReq=Ionizer On ，且空气净化开启时显示空气净化标识（AC发送ID340 AC_PlasmaSt=inactive给HU） | H21: 1 | I21: 仿真
A22: 15 | B22: 蓝牙电话 | C22: I208BT电话需求规格说明书-V4.0-3.1 BT设置3.1.1 开关功能 | D22: F-BT开关设置 | E22: BT电话app能打开 | F22: 1.点击BT的开启开关，查看是否能正常打开和关闭； | G22: 1.BT开关可以正常打开和关闭； | H22: 1 | I22: 台架
A23: 16 | B23: 蓝牙电话 | C23: I208BT电话需求规格说明书-V4.0-3.4 通话 | D23: F-车端拨打电话声音 | E23: BT已连接 | F23: 1.车机端拨打电话，联系人婷婷 1521458887 2.查看去电声音通道 | G23: 1.去电时，默认经由车机端的扬声器输出声音 | H23: 1 | I23: 台架
A24: 17 | B24: 蓝牙电话 | C24: I208BT电话需求规格说明书-V4.0-3.1 BT设置 | D24: F-同步联系人开关开启是否能正常导入手机端的sim卡上的通讯录 | E24: 1.BT已配对连接 2.同步联系人开关开启 | F24: 1.BT配对连接成功后查看手机上sim卡中的通讯录是否在车机端中 | G24: 可以把已连接手机sim卡中的通讯录同步至车机端的电话簿中 | H24: 1 | I24: 台架
A25: 18 | B25: 全景影像 | C25: I223-3全景影像显示需求规格说明书-V1.0（内置）3.1.1.1 视图界面 | D25: F—启动画面显示 | E25: 1.电源非 OFF 档 2.全景影像激活状态 | F25: 1.通过车机AVM触发进入全景模式； 2.进入全景后，界面选择关闭按钮退出全景； | G25: 1.直接进入全景界面； 2.选择关闭后，退出全景界面； | H25: 1 | I25: 台架
A26: 19 | B26: 升级 | C26: FOTA2.0功能需求文档-1.6-USB升级 | D26: F-U盘升级功能测试 | E26: 1.U盘中有需要升级的目录，包含3个车载类升级对象（4G/MCU/HU OS），每一个升级对象都必须具备三个文件：安装包、版本文件、校验码文件，目录格式参考“USB升级目录格式” | F26: 1.未插入U盘前进入USB升级； 2.插入U盘，选择一键安装； | G26: 1.显示"未插入U盘" 2.进入升级后正常显示进度条，升级成功，查看OS/MCU/4G版本号正确； | H26: 1 | I26: 台架
A27: 20 | B27: 文件管理 | C27: USB(I209.01.01.00) | D27: F-识别USB连接 | E27: 插上U盘 | F27: 上电开机进入文件管理 | G27: 页面左侧文件源USB储存可选择 | H27: 1 | I27: 台架
A28: 21 | B28: 文件管理 | C28: 音频文件列表(I209.02.01.00) | D28: F-音频播放 | E28: 1.进入文件管理 2.选择USB储存 3.打开音频列表 | F28: 点击正在播放的歌曲 | G28: 取消播放 | H28: 1 | I28: 台架
A29: 22 | B29: 文件管理 | C29: 图片文件列表(I209.02.02.00) | D29: F-图片浏览模式 | E29: 1.进入文件管理 2.选择USB储存 3.打开图片列表 | F29: 可直接点击图片文件 | G29: 进入图片浏览模式 | H29: 1 | I29: 台架
A30: 23 | B30: 文件管理 | C30: 视频文件列表(I209.02.03.00) | D30: F-打开视频进入播放器 | E30: 1.进入文件管理 2.选择USB储存 3.打开视频列表 | F30: 可直接点击视频文件 | G30: 进入“视频播放器”播放选择的视频 | H30: 1 | I30: 台架
A31: 24 | B31: 系统设置 | C31: I215系统设置需求规格说明书-V2.2-触摸提示音 | D31: F-系统设置下触摸提示音功能 | E31: 1.车机支持触控按键 2.进入系统设置→触摸提示音 | F31: 1.开启触摸提示音，点击当前页面触控按键； 2.关闭触摸提示音，点击当前页面触控按键； | G31: 1.有触摸提示音发出，用户可以感知到声音； 2.无触摸提示音发出； | H31: 1 | I31: 台架
A32: 25 | B32: 系统设置 | C32: I215系统设置需求规格说明书-V2.2-关闭屏幕 | D32: S-关闭屏幕基础功能 | E32: 1.之前未调整过关屏效果 | F32: 1.进入系统设置→显示设置，点击“关闭屏幕”； 2.再次点击按钮“打开屏幕”； | G32: 1.屏幕立即关闭，显示默认关屏效果，为模拟时钟； 2.点亮屏幕； | H32: 1 | I32: 台架
... A39: 32 | B39: 系统设置 | C39: I215系统设置需求规格说明书-V2.2-移动网络 | D39: F-wifi热点基础设置 | E39: 1.之前未进行过wifi热点的开关设置 | F39: 1.查看系统wifi热点开关默认状态； 2.其他设备连接车机开启的热点； | G39: 1.wifi热点默认为关闭； 2.其他设备可以通过wifi热点连接访问网络； | H39: 1 | I39: 台架
A40: 33 | B40: 语音唤醒 | D40: F-语音唤醒启动语音 | E40: 1.车机正常使用状态下 | F40: 1. 语音输入“小安你好”或者自定义唤醒词 | G40: 1.语音反馈“嗨”等应答词语并进入语音录音界面 | H40: 1 | I40: 台架
A41: 34 | B41: 主页 | D41: 主页UI基础检查 | E41: 1.THU已上电开机 | F41: 1.检查所有主页和APPlist的UI分布有无明显异常； | G41: 1.主页UI和APPlist UI显示无异常； | H41: 1 | I41: 台架

Sheet AI主页
A1: 总用例 | B1: 116 | C1: XX零部件测试AI主页用例
A2: passed | B2: =COUNTIF(J:J,"=passed") -> 0
A3: failed | B3: =COUNTIF(J:J,"=failed") -> 0
A4: blocked | B4: =COUNTIF(J:J,"=blocked") -> 0
A5: N/A | B5: =COUNTIF(J:J,"=N/A") -> 0
A6: 项目名称：XXX | C6: 版本: | E6: 编制: | G6: 测试人员: | I6: 测试日期:
A7: 用例序号 | B7: 所属模块 | C7: 相关需求 | D7: 用例标题 | E7: 前置条件 | F7: 步骤 | G7: 预期 | H7: 优先级 | I7: 用例执行方式 | J7: 用例执行结果 | K7: DTM缺陷号
A8: 1 | B8: AI主页 | C8: 4.1.1 全局-左边栏 | D8: F-进入AI主页 | E8: 打开全局-左边栏 | F8: 点击AI主页 | G8: 进入AI主页 | H8: 1 | I8: 台架
A9: 2 | B9: AI主页 | C9: 4.1.1 全局-左边栏 | D9: F-进入地图主页 | E9: 打开全局-左边栏 | F9: 点击地图主页 | G9: 进入地图主页 | H9: 2 | I9: 台架
A10: 3 | B10: AI主页 | C10: 4.1.1 全局-左边栏 | D10: F-进入娱乐主页 | E10: 打开全局-左边栏 | F10: 点击娱乐主页 | G10: 进入娱乐主页 | H10: 2 | I10: 台架
A11: 4 | B11: AI主页 | C11: 4.1.1 全局-左边栏 | D11: F-进入车主页 | E11: 打开全局-左边栏 | F11: 点击车主页 | G11: 进入车主页 | H11: 2 | I11: 台架
A12: 5 | B12: AI主页 | C12: 4.1.1 全局-左边栏 | D12: F-进入车主页 | E12: 打开全局-左边栏 | F12: 点击全量应用 | G12: 进入车全量应用主页 | H12: 2 | I12: 台架
A13: 6 | B13: AI主页 | C13: 4.1.1 全局-左边栏 | D13: F-默认展示AI主页 | E13: 首次开机 | F13: 查看主页页面展示 | G13: 默认展示AI主页 | H13: 2 | I13: 台架
A14: 7 | B14: AI主页 | C14: 4.1.1 全局-左边栏 | D14: F-后续开机主页为上次开机设置主页 | E14: / | F14: 1.将开机主页设置为娱乐主页 2.关机重启 | G14: 开机主页为娱乐主页 | H14: 2 | I14: 台架
A15: 8 | B15: AI主页 | C15: 4.1.2 状态栏 | D15: F-上方状态栏包括三个部分 | E15: 页面上方状态栏包括三个部分 | F15: 查看展示 | G15: 语音交互区、下拉菜单引导区、状态显示栏区 | H15: 1 | I15: 台架
A16: 9 | B16: AI主页 | C16: 4.1.2.1 语音交互区 | D16: F-语音交互区包括三部分 | E16: 语音交互区包括三部分 | F16: 查看展示 | G16: 语音助手形象、语音提示区、语音打字机 | H16: 1 | I16: 台架
A17: 10 | B17: AI主页 | C17: 4.1.2.1 语音交互区 | D17: F-语助唤醒、休眠 | E17: / | F17: 点击长安语助形象图标 | G17: 语助唤醒/休眠 | H17: 2 | I17: 台架
A18: 11 | B18: AI主页 | C18: 4.1.2.1 语音交互区 | D18: F-语助形象，声源定位区分 | E18: / | F18: 分别进行主驾、副驾语音控制 | G18: 主驾、副驾（不同方位）语音语助有不同的状态 | H18: 2 | I18: 台架
A19: 12 | B19: AI主页 | C19: 4.1.2.1 语音交互区 | D19: F-显示语音打字机识别结果 | E19: 免唤醒时间内 | F19: 语音录入 | G19: 可将语音实时转化为文字 | H19: 2 | I19: 台架
... A106: 99 | B106: AI主页 | C106: 4.2.3.1 视频推荐 | D106: F-视频推荐 已登录点击卡片 | E106: 已登录 | F106: 1.打开快捷区推荐卡片 2.点击卡片 | G106: 直接进入爱奇艺播放界面进行播放 | H106: 1 | I106: 台架
A107: 100 | B107: AI主页 | C107: 4.2.3.3 美食推荐 | D107: F-美食推荐数据 | F107: 1.打开快捷区推荐卡片 2.点击卡片 | G107: 进入对应小程序 | H107: 1 | I107: 台架
A108: 101 | B108: AI主页 | C108: 4.2.3.4 智能日程 | D108: F-无待办日程 | E108: 无待办日程 | F108: / | G108: 显示无待办日程 | H108: 2 | I108: 台架
A109: 102 | B109: AI主页 | C109: 4.2.3.4 智能日程 | D109: F-有待办日程 | E109: 已新建待办日程 | F109: / | G109: 1.显示待办事项及时间，最多同时显示四条日程 2.优先展示临近时间日程 3.日程完成后从列表清除 | H109: 2 | I109: 台架
A110: 103 | B110: AI主页 | C110: 4.3 地图区 | D110: F-地图区，导航未开启时 | E110: 导航未开启时 | F110: 打开地图 | G110: 地图区域显示地图巡航转状态的图片，实时显示车辆定位 | H110: 2 | I110: 台架
A111: 104 | B111: AI主页 | C111: 4.3 地图区 | D111: F-地图区，导航未开启时，未设置家的位置 | E111: 导航未开启时，未设置家的位置 | F111: 1.打开地图 2.点击家图标 | G111: 进入导航主页设置家和公司的位置 | H111: 1 | I111: 台架
A112: 105 | B112: AI主页 | C112: 4.3 地图区 | D112: F-地图区，导航未开启时，未设置公司位置 | E112: 导航未开启时，未设置公司位置 | F112: 1.打开地图 2.点击公司图标 | G112: 进入导航主页设置家和公司的位置 | H112: 2 | I112: 台架
A113: 106 | B113: AI主页 | C113: 4.3 地图区 | D113: F-地图区，导航未开启时，已设置家位置 | E113: 导航未开启时，已设置家位置 | F113: 1.打开地图 2.点击家图标 | G113: 1.直接跳转导航地图线路规划界面 2.选择后可直接开始导航 | H113: 1 | I113: 台架
A114: 107 | B114: AI主页 | C114: 4.3 地图区 | D114: F-地图区，导航未开启时，已设置公司位置 | E114: 导航未开启时，已设置公司位置 | F114: 1.打开地图 2.点击公司图标 | G114: 1.直接跳转导航地图线路规划界面 2.选择后可直接开始导航 | H114: 2 | I114: 台架
A115: 108 | B115: AI主页 | C115: 4.3 地图区 | D115: F-导航已开启时 | E115: 导航已开启时 | F115: 1.打开地图 2.查看地图界面展示 | G115: 地图区域显示导航小地图信息及 TBT、光柱图、距离目的地距离及时间 | H115: 2 | I115: 台架
A116: 109 | B116: AI主页 | C116: 4.4 空调区 | D116: F-空调区状态信息 | E116: / | F116: 1.显示空调状态信息（风量、温度、风向、模式） 2.点击卡片 | G116: 进入空调设置界面 | H116: 2 | I116: 台架
A117: 110 | B117: AI主页 | C117: 4.5 天气区 | D117: F-天气区展示 | E117: / | F117: 天气区上方区域下方区域展示 | G117: 上方区域常显示实时位置的天气（2h 更新一次）和空气质量，下方区域显示限行尾号 | H117: 2 | I117: 台架
A118: 111 | B118: AI主页 | C118: 4.5 天气区 | D118: F-天气区交互 | E118: / | F118: 天气区--点击图标 | G118: 进入天气 APP 界面 | H118: 2 | I118: 台架
A119: 112 | B119: AI主页 | C119: 4.6 智慧家居 | D119: F-家居模式未登录 | E119: 未登录 | F119: 1.打开智慧家居 2.点击回家按钮 | G119: 示跳转智慧物联 APP 登录界面 | H119: 1 | I119: 台架
... A123: 116 | B123: AI主页 | C123: 4.6 智慧家居 | D123: F-抽烟模式 | E123: / | F123: 1.打开智慧家居 2.点击图标 | G123: 打开抽烟模式，再次点击关闭 | H123: 1 | I123: 台架

Sheet 娱乐主页&QQ音乐&喜马拉雅
A1: 总用例 | B1: 145 | C1: XXX零部件测试娱乐主页用例
A2: passed | B2: =COUNTIF(J:J,"=passed") -> 0
A3: failed | B3: =COUNTIF(J:J,"=failed") -> 0
A4: blocked | B4: =COUNTIF(J:J,"=blocked") -> 0
A5: N/A | B5: =COUNTIF(J:J,"=N/A") -> 0
A6: 项目名称：XXX | C6: 版本: | E6: 编制: | G6: 测试人员: | I6: 测试日期:
A7: 用例序号 | B7: 所属模块 | C7: 相关需求 | D7: 用例标题 | E7: 前置条件 | F7: 步骤 | G7: 预期 | H7: 优先级 | I7: 用例执行方式 | J7: 用例执行结果 | K7: DTM缺陷号
A8: 1 | B8: 娱乐主页 | C8: 长安CD569项目娱乐主页PRD需求文档20200525-4.1 全局说明 | D8: F-查看娱乐主页界面是否与设计一致 | E8: 1.车机正常使用状态 | F8: 1.进入娱乐主页，查看界面 | G8: 1.界面排版、色彩、字体、模块与设计保持一致 | H8: 2 | I8: 台架
A9: 2 | B9: 娱乐主页 | C9: 长安CD569项目娱乐主页PRD需求文档20200525-4.2 全局搜索 | D9: F-全局搜索界面排版 | E9: 1.车机正常使用状态 | F9: 1.点击搜索按钮，查看界面 | G9: 1.与设计保持一致。搜索记录横排显示，最多显示一行。热搜词最多显示一排，无网络时不显示 | H9: 2 | I9: 台架
A10: 3 | B10: 娱乐主页 | C10: 长安CD569项目娱乐主页PRD需求文档20200525-4.2 全局搜索 | D10: F-输入关键字后界面显示 | E10: 1.车机正常使用状态 | F10: 1.在搜索框中输入关键字 | G10: 1.输入关键词后，联想词横向排放，最多显示两排。 | H10: 2 | I10: 台架
A11: 4 | B11: 娱乐主页 | C11: 长安CD569项目娱乐主页PRD需求文档20200525-4.2 全局搜索 | D11: F-有结果时点击对应模块显示对应的搜索结果 | E11: 1.车机正常使用状态 | F11: 1.有搜索结果时，点击对应模块 | G11: 1.会显示对应音源的搜索结果 | H11: 1 | I11: 台架
A12: 5 | B12: 娱乐主页 | C12: 长安CD569项目娱乐主页PRD需求文档20200525-4.3AI频道-4.3.1音频内容来源 | D12: F-查看AI频道中的内容 | E12: 1.车机正常使用状态 2.网络已连接 | F12: 1.点击AI频道，查看内容 | G12: 1.内容由喜马拉雅提供（节目和音乐），优先提供更新的节目，并且这些音频都是免费的 | H12: 2 | I12: 台架
A13: 6 | B13: 娱乐主页 | C13: 长安CD569项目娱乐主页PRD需求文档20200525-4.3AI频道-4.3.2 音频内容要求 | D13: F-查看AI频道中的节目时长划分 | E13: 1.车机正常使用状态 2.网络已连接 | I13: 台架
A14: 7 | B14: 娱乐主页 | C14: 长安CD569项目娱乐主页PRD需求文档20200525-4.3AI频道-4.3.2 音频内容要求 | D14: F-查看AI频道中的节目分类 | E14: 1.车机正常使用状态 2.网络已连接 | F14: 1.点击AI频道，查看内容中的节目分类 | G14: 1.节目内容只出现 商业财经、IT科技、旅游、电影、时尚生活、娱乐、头条、脱口秀、情感生活 这9个 | H14: 2 | I14: 台架
A15: 8 | B15: 娱乐主页 | C15: 长安CD569项目娱乐主页PRD需求文档20200525-4.3AI频道-4.3.2 音频内容要求 | D15: F-查看AI频道中的音乐分类 | E15: 1.车机正常使用状态 2.网络已连接 | F15: 1.点击AI频道，查看内容中的音乐分类 | G15: 1.音乐中展示 流行、摇滚、民谣、轻音乐、古风、爵士、乡村等43个类别 | H15: 2 | I15: 台架
A16: 9 | B16: 娱乐主页 | C16: 长安CD569项目娱乐主页PRD需求文档20200525-4.3AI频道-4.3.2 音频内容要求 | D16: F-AI 频道播放的内容需要和车机用户账号（Uid）进行绑定 | E16: 1.车机正常使用状态 2.网络已连接 | I16: 台架
A17: 10 | B17: 娱乐主页 | C17: 长安CD569项目娱乐主页PRD需求文档20200525-4.3AI频道-4.3.3 推荐 | D17: S-查看早高峰：6：00-8：59时，AI频道推送内容 | E17: 1.车机正常使用状态 2.网络已连接 3.时间为6：00-8：59 | F17: 1.点击AI频道，查看场景化推荐内容 | G17: 1.音乐：轻音乐、民谣、乡村、流行、R&B； 节目：IT 科技、商业财经、头条、娱乐、脱口秀 | H17: 1 | I17: 台架
A18: 11 | B18: 娱乐主页 | C18: 长安CD569项目娱乐主页PRD需求文档20200525-4.3AI频道-4.3.3 推荐 | D18: S-查看上午：9：00~11：59时，AI频道推送内容 | E18: 1.车机正常使用状态 2.网络已连接 3.时间为上午：9：00~11：59时 | F18: 1.点击AI频道，查看场景化推荐内容 | G18: 1.音乐：摇滚、欧美、嘻哈、电子、民谣、流行 节目：时尚生活、电影、脱口秀、旅 游、商业财经、IT 科技 | H18: 1 | I18: 台架
A19: 12 | B19: 娱乐主页 | C19: 长安CD569项目娱乐主页PRD需求文档20200525-4.3AI频道-4.3.3 推荐 | D19: S-查看中下午：12：00~16：59时，AI频道推送内容 | E19: 1.车机正常使用状态 2.网络已连接 3.时间为中下午：12：00~16：59 | F19: 1.点击AI频道，查看场景化推荐内容 | G19: 1.音乐：摇滚、欧美、嘻哈、电子、流行 节目：时尚生活、电影、脱口秀、旅 游、商业财经、IT 科技 | H19: 1 | I19: 台架
A20: 13 | B20: 娱乐主页 | C20: 长安CD569项目娱乐主页PRD需求文档20200525-4.3AI频道-4.3.3 推荐 | D20: S-查看晚高峰：17：00~19：59时，AI频道推送内容 | E20: 1.车机正常使用状态 2.网络已连接 3.时间为晚高峰：17：00~19：59 | F20: 1.点击AI频道，查看场景化推荐内容 | G20: 1.音乐：流行、摇滚、说唱、R&B 节目：旅游、电影、时尚生活、娱 乐、头条、脱口秀 | H20: 1 | I20: 台架
A21: 14 | B21: 娱乐主页 | C21: 长安CD569项目娱乐主页PRD需求文档20200525-4.3AI频道-4.3.3 推荐 | D21: S-查看晚上：20：00~21：59时，AI频道推送内容 | E21: 1.车机正常使用状态 2.网络已连接 3.时间为晚上：20：00~21：59 | F21: 1.点击AI频道，查看场景化推荐内容 | G21: 1.音乐：爵士、古风、R&B、民谣、流行、萨克斯 节目：情感、旅游、时尚生活、脱口 秀、电影 | H21: 1 | I21: 台架
A22: 15 | B22: 娱乐主页 | C22: 长安CD569项目娱乐主页PRD需求文档20200525-4.3AI频道-4.3.3 推荐 | D22: S-查看深夜：22：00~00：59时，AI频道推送内容 | E22: 1.车机正常使用状态 2.网络已连接 3.时间为深夜：22：00~00：59 | F22: 1.点击AI频道，查看场景化推荐内容 | G22: 1.音乐：爵士、古风、R&B、民谣、流行、萨克斯 节目：情感、旅游、电影 | H22: 1 | I22: 台架
A23: 16 | B23: 娱乐主页 | C23: 长安CD569项目娱乐主页PRD需求文档20200525-4.3AI频道-4.3.3 推荐 | D23: S-查看凌晨：1：00~05：59时，AI频道推送内容 | E23: 1.车机正常使用状态 2.网络已连接 3.时间为凌晨：1：00~05：59 | F23: 1.点击AI频道，查看场景化推荐内容 | G23: 1.音乐：流行、民谣、R&B、欧美、日本 节目：商业财经、IT 科技、旅游、电影、时尚生活、娱乐、头条、脱口 秀、情感生活 | H23: 1 | I23: 台架
A24: 17 | B24: 娱乐主页 | C24: 长安CD569项目娱乐主页PRD需求文档20200525-4.3AI频道-4.3.3 推荐 | D24: S-查看堵车时，AI频道推送内容 | E24: 1.车机正常使用状态 2.网络已连接 3.处于堵车状态 | F24: 1.点击AI频道，查看场景化推荐内容 | G24: 1.音乐：R&B、说唱、流行、 节目：时尚生活、娱乐、头条 | H24: 1 | I24: 台架
A25: 18 | B25: 娱乐主页 | C25: 长安CD569项目娱乐主页PRD需求文档20200525-4.3AI频道-4.3.3 推荐 | D25: S-查看高速时，AI频道推送内容 | E25: 1.车机正常使用状态 2.网络已连接 3.高速行驶中 | F25: 1.点击AI频道，查看场景化推荐内容 | G25: 1.音乐：摇滚、说唱、电音、流行 节目：时尚生活、娱乐、旅游、电影 | H25: 2 | I25: 台架
A26: 19 | B26: 娱乐主页 | C26: 长安CD569项目娱乐主页PRD需求文档20200525-4.3AI频道-4.3.3 推荐 | D26: S-查看早高峰堵车时，AI频道推送内容 | E26: 1.车机正常使用状态 2.网络已连接 3.时间为6：00-8：59，堵车 | F26: 1.点击AI频道，查看场景化推荐内容 | G26: 1.音乐：轻音乐、民谣、乡村、流行、R&B； 节目：IT 科技、商业财经、头条、娱乐、脱口秀 | H26: 2 | I26: 台架
A27: 20 | B27: 娱乐主页 | C27: 长安CD569项目娱乐主页PRD需求文档20200525-4.3AI频道-4.3.3 推荐 | D27: F-个性化推荐 | E27: 1.车机正常使用状态 2.网络已连接 | F27: 1.点击AI频道，查看个性化推荐内容 | G27: 1.结合用户画像和用户行为分析，建立用户收听偏好和音频内容的映射关系，推荐用户想要收听的内容 | H27: 2 | I27: 台架
A28: 21 | B28: 娱乐主页 | C28: 长安CD569项目娱乐主页PRD需求文档20200525-4.3AI频道-4.3.3 推荐 | D28: F-AI推荐推送内容配比 | E28: 1.车机正常使用状态 2.网络已连接 | F28: 1.点击AI频道，查看推荐内容 | G28: 1 1个歌曲+5个短时节目+1个中时节目+2个歌曲+1个长时节目/2个歌曲+4个短时节目+2个中时节目+3个歌曲+1 个长时节目/3个歌曲+3个短时节目+2个中时节目+2个歌曲+1个长时节目/3个歌曲+4个短时节目+2个中时节目+3个歌曲+1个长时节目 | H28: 1 | I28: 台架
... A51: 44 | B51: 娱乐主页 | C51: 长安CD569项目娱乐主页PRD需求文档20200525-4.4QQ音乐-4.4.2 我的-4.4.2.3 我的账户 | D51: F-用户登陆后，不展示随便听听入口 | E51: 1.车机正常使用状态 2.网络已连接 3.用户已登录 | F51: 1.打开QQ音乐 | G51: 1.不展示随便听听入口 | H51: 2 | I51: 台架
A52: 45 | B52: 娱乐主页 | C52: 长安CD569项目娱乐主页PRD需求文档20200525-4.4QQ音乐-4.4.2 我的-4.4.2.3 我的账户 | D52: F-播放随便听听时登陆账号 | E52: 1.车机正常使用状态 2.网络已连接 | F52: 1.播放随便听听 2.登陆账号 | G52: 2.歌曲继续播放，播完后。。。 | I52: 台架
A53: 46 | B53: 娱乐主页 | C53: 长安CD569项目娱乐主页PRD需求文档20200525-4.4QQ音乐-4.4.2 我的-4.4.2.3 我的账户 | D53: F-用户登陆后，查看用户的信息 | E53: 1.车机正常使用状态 2.网络已连接 3.用户已登录 | F53: 1.进入到我的账户 | G53: 1.可以查看用户账户的信息：昵称、头像、会员信息、会员标识。 | H53: 2 | I53: 台架
A54: 47 | B54: 娱乐主页 | C54: 长安CD569项目娱乐主页PRD需求文档20200525-4.4QQ音乐-4.4.2 我的-4.4.2.3 我的账户 | D54: F-用户登陆后，购买会员 | E54: 1.车机正常使用状态 2.网络已连接 3.用户已登录 | F54: 1.进入到我的账户 2.点击绿钻标识 | G54: 1.非绿钻会员用户点击绿钻标识，则进入到绿钻购买页面；绿钻会员用户点击绿钻标识，进入到绿钻续费页面。 | H54: 1 | I54: 台架
A55: 48 | B55: 娱乐主页 | C55: 长安CD569项目娱乐主页PRD需求文档20200525-4.4QQ音乐-4.4.2 我的-4.4.2.4 播放器 | D55: F-播放歌曲时,查看播放器界面 | E55: 1.车机正常使用状态 2.网络已连接 3.用户已登录 4.歌曲播放中 | F55: 1.进入播放器界面 | G55: 1.界面展示歌曲名、歌手名、歌曲封面、歌词、音源图标、播放进度（蓝牙音乐需要展示播放进度条） | H55: 2 | I55: 台架
A56: 49 | B56: 娱乐主页 | C56: 长安CD569项目娱乐主页PRD需求文档20200525-4.4QQ音乐-4.4.2 我的-4.4.2.4 播放器 | D56: F-在播放器界面点击歌手名会跳转到搜索界面 | E56: 1.车机正常使用状态 2.网络已连接 3.用户已登录 4.歌曲播放中 | F56: 1.在播放器界面点击歌手名 | G56: 1.把歌手名带入到搜索框进行搜索，无法获取时不显示 | H56: 2 | I56: 台架
A57: 50 | B57: 娱乐主页 | C57: 长安CD569项目娱乐主页PRD需求文档20200525-4.4QQ音乐-4.4.2 我的-4.4.2.4 播放器 | D57: F-切换到上一曲 | E57: 1.车机正常使用状态 2.网络已连接 3.任意播放模式 4.歌曲播放中 | F57: 1.点击上一曲按钮 | G57: 1.能正常切换歌曲(当前歌曲为列表第一首时,切换到列表最后一首) | H57: 1 | I57: 台架
A58: 51 | C58: 长安CD569项目娱乐主页PRD需求文档20200525-4.4QQ音乐-4.4.2 我的-4.4.2.4 播放器 | D58: F-切换到下一曲 | E58: 1.车机正常使用状态 2.网络已连接 3.任意播放模式 4.歌曲播放中 | F58: 1.点击下一曲按钮 | G58: 1.能正常切换歌曲(当前歌曲为列表最后一首时,切换到列表第一首) | H58: 1 | I58: 台架
A59: 52 | B59: 娱乐主页 | C59: 长安CD569项目娱乐主页PRD需求文档20200525-4.4QQ音乐-4.4.2 我的-4.4.2.4 播放器 | D59: F-控制歌曲暂停/播放 | E59: 1.车机正常使用状态 2.网络已连接 3.任意播放模式 4.歌曲播放中 | F59: 1.点击暂停/播放按钮 | G59: 1.能正常控制歌曲播放或暂停 | H59: 1 | I59: 台架
A60: 53 | B60: 娱乐主页 | C60: 长安CD569项目娱乐主页PRD需求文档20200525-4.4QQ音乐-4.4.2 我的-4.4.2.4 播放器 | D60: F-控制歌曲快进 | E60: 1.车机正常使用状态 2.网络已连接 3.任意播放模式 4.歌曲播放中 | F60: 1.长按下一曲按钮 | G60: 1.以5X的速度快进，当用户释放按钮时，停止快进；如果到达当前曲目的末尾，将切换到下一首歌曲以正常速度播放 | H60: 1 | I60: 台架
A61: 54 | B61: 娱乐主页 | C61: 长安CD569项目娱乐主页PRD需求文档20200525-4.4QQ音乐-4.4.2 我的-4.4.2.4 播放器 | D61: F-控制歌曲快退 | E61: 1.车机正常使用状态 2.网络已连接 3.任意播放模式 4.歌曲播放中 | F61: 1.长按上一曲按钮 | G61: 1.以 5X 的速度快退，当用户释放按钮时，停止快退；如果到 达当前曲目的开头，将停止快退并以正常速度开始播放当前歌曲 | H61: 1 | I61: 台架
A62: 55 | B62: 娱乐主页 | C62: 长安CD569项目娱乐主页PRD需求文档20200525-4.4QQ音乐-4.4.2 我的-4.4.2.4 播放器 | D62: F-多次点击循环模式按钮,查看播放模式 | E62: 1.车机正常使用状态 2.网络已连接 3.歌曲播放中 | F62: 1.多次点击播放模式按钮 | G62: 1.播放模式依次为顺序循环→单曲循环→随机循环→顺序循环 | H62: 1 | I62: 台架
...

Sheet 本地&蓝牙音乐
A1: 总用例 | B1: 148 | C1: XXX零部件测试本地&蓝牙音乐用例
A2: passed | B2: =COUNTIF(J:J,"=passed") -> 0
A3: failed | B3: =COUNTIF(J:J,"=failed") -> 0
A4: blocked | B4: =COUNTIF(J:J,"=blocked") -> 0
A5: N/A | B5: =COUNTIF(J:J,"=N/A") -> 0
A6: 项目名称：XXX | C6: 版本: | E6: 编制: | G6: 测试人员: | I6: 测试日期:
A7: 用例序号 | B7: 所属模块 | C7: 相关需求 | D7: 用例标题 | E7: 前置条件 | F7: 步骤 | G7: 预期 | H7: 优先级 | I7: 用例执行方式 | J7: 用例执行结果 | K7: DTM缺陷号
A8: 1 | B8: 本地&蓝牙音乐 | C8: I206本地音乐需求规格说明书-V1.3 -2.7 性能指标 | D8: F—手机第三方播放器兼容性 | E8: 蓝牙已连接 | F8: 1.在手机中安装好第三方播放器虾米音乐 、天天动听 、网易云音乐 、咪咕音乐 、General Media Player 、iTunes、天天动听、酷狗音乐、酷我音乐、qq 音乐进行蓝牙音乐播放 | G8: 1.都能成功播放音乐，且音质好 | H8: 2 | I8: 台架
A9: 2 | B9: 本地&蓝牙音乐 | C9: I206本地音乐需求规格说明书-V1.3 -2.7 性能指标 | D9: F—USB设备音频文件支持格式 | E9: USB设备已插入 | F9: 1.在USB设备中放入不同音频格式*.AAC、*.MP3、*.MP2、*.WAV、*.WMA、*.OGG、*.AMR、*.APE、*.FLAC、*.M4A、*.M4R、*.MMF进行播放 | G9: 1.都能成功播放音乐，且音质好 | H9: 1 | I9: 台架
A10: 3 | B10: 本地&蓝牙音乐 | C10: I206本地音乐需求规格说明书-V1.3 -3.3节目信息显示3.3.4 专辑图片 | D10: F—专辑图片格式 | E10: 有音乐 | F10: 1.找到专辑图片分别为*.JPEG、*.GIF(仅静态第一帧)、*.PNG、*.BMP、*.webp的音乐进行播放 | G10: 1.图片格式都支持，且正常显示 | H10: 2 | I10: 台架
A11: 4 | B11: 本地&蓝牙音乐 | C11: I206本地音乐需求规格说明书-V1.3 -2.7 性能指标 | D11: F—音乐应用首次 启动（冷启动）所需时间 | E11: 车机已上电 | F11: 1.车机第一次启动后打开音乐应用，查看所需时间 | G11: 1.所需时间≤2s | H11: 2 | I11: 台架
A12: 5 | B12: 本地&蓝牙音乐 | C12: I206本地音乐需求规格说明书-V1.3 -2.7 性能指标 | D12: F—音乐应用后台 启动（热启动）所需时间 | E12: 车机已上电 | F12: 1.打开音乐、导航、设置、电台等应用，让音乐应用再后台运行 2.打开音乐，查看所需时间 | G12: 1.所需时间≤500ms | H12: 2 | I12: 台架
A13: 6 | B13: 本地&蓝牙音乐 | C13: I206本地音乐需求规格说明书-V1.3 -2.7 性能指标 | D13: F—点击按键响应 所需时间 | E13: 车机已上电 | F13: 1.点击车机上的不同按键，查看所需时间 | G13: 1.所需时间≤500ms | H13: 2 | I13: 台架
A14: 7 | B14: 本地&蓝牙音乐 | C14: I206本地音乐需求规格说明书-V1.3 -2.7 性能指标 | D14: F—各页面切换时间 | E14: 车机已上电 | F14: 1.车机上切换不同页面，查看切换所需时间 | G14: 1.所需时间≤1s | H14: 2 | I14: 台架
A15: 8 | B15: 本地&蓝牙音乐 | C15: I206本地音乐需求规格说明书-V1.3 -2.7 性能指标 | D15: F—蓝牙音乐播放状态同步所需时间 | E15: 蓝牙已连接 | F15: 1.手机上播放音乐，查看车机上播同步状态所需时间 | G15: 1.所需时间≤200ms | H15: 2 | I15: 台架
A16: 9 | B16: 本地&蓝牙音乐 | C16: I206本地音乐需求规格说明书-V1.3 -2.7 性能指标 | D16: F—蓝牙音乐信息 同步延时 所需时间 | E16: 蓝牙已连接 | F16: 1.手机上播放音乐，查看车机上音乐信息 同步延时 所需时间 | G16: 1.所需时间≤200ms | H16: 2 | I16: 台架
A17: 10 | B17: 本地&蓝牙音乐 | C17: I206本地音乐需求规格说明书-V1.3—3.1 音源选择3.1.2 USB | D17: S—无音频文件的U盘 | E17: 车机已上电 | F17: 1.车机处于主界面 2.接无音频文件的U盘 | G17: 1.车机自动切换至 USB 音乐源 2.不会自动播放 | H17: 2 | I17: 台架
A18: 11 | B18: 本地&蓝牙音乐 | C18: I206本地音乐需求规格说明书-V1.3—3.1 音源选择3.1.2 USB | D18: S—接有音频文件的U盘 | E18: 车机已上电 | F18: 1.车机处于主界面 2.接有音频文件的U盘 | G18: 1.切换到 USB 音乐源并自动播放第一个识别出来的音频文 件 | H18: 1 | I18: 台架
A19: 12 | B19: 本地&蓝牙音乐 | C19: I206本地音乐需求规格说明书-V1.3—3.1 音源选择3.1.2 USB | D19: S—未插入U盘 | E19: 车机已上电 | F19: 1.车机打开后不插入U盘，点击USB音乐源 | G19: 1.无法切 换为 USB 音乐源，USB 音乐源置灰 | H19: 3 | I19: 台架
... A155: 148 | B155: 本地&蓝牙音乐 | C155: I206本地音乐需求规格说明书-V1.3—3.8 双屏互动（全液晶 IP)3.8.2 音乐常显 3.8.2.1.2 业务逻辑 | D155: S—仪表回到场景重构 | E155: 1.车辆处于非 OFF 档 2.音乐播放中 3.IP当前优先级低于(哪些页面低)音乐界面 | F155: 1.在中控音乐界面屏 幕任意位置三/四指左滑 2.长按MODE关闭中控等多种关闭 多媒体音源的方式 | G155: 1.IP显示音乐播放界面 2.IP回到场景重构 3.播放状态为：停止 | H155: 2 | I155: 台架

Sheet 车主页
A1: 总用例 | B1: 30 | C1: XXX零部件测试车主页用例
A2: passed | B2: =COUNTIF(J:J,"=passed") -> 0
A3: failed | B3: =COUNTIF(J:J,"=failed") -> 0
A4: blocked | B4: =COUNTIF(J:J,"=blocked") -> 0
A5: N/A | B5: =COUNTIF(J:J,"=N/A") -> 0
A6: 项目名称：XXX | C6: 版本: | E6: 编制: | G6: 测试人员: | I6: 测试日期:
A7: 用例序号 | B7: 所属模块 | C7: 相关需求 | D7: 用例标题 | E7: 前置条件 | F7: 步骤 | G7: 预期 | H7: 优先级 | I7: 用例执行方式 | J7: 用例执行结果 | K7: DTM缺陷号
A8: 1 | B8: 4. 功能设计 | C8: 4.2.1 3D 车模区 | D8: F-3D车模同步进行可视化变化 | E8: 通过控件控制车辆相关部件 如：开启天窗 | F8: 1.打开3D车控区 2.天窗控制栏打开天窗 | G8: 触发动画3D车模同步开启天窗 | H8: 2 | I8: 台架
A9: 2 | B9: 4. 功能设计 | C9: 4.2.1 3D 车模区 | D9: F-实时显示已行驶里程数 | E9: 已行驶300KM | F9: 查看车模上方展示 | G9: 车模上方实时显示您已行驶300KM | H9: 2 | I9: 台架
A10: 3 | B10: 4. 功能设计 | C10: 4.2.2 车控区 | D10: F-车控区展示 | E10: 车辆控制快捷功能分三页展示 | F10: 可左右滑动 | G10: 可通过滑动进行切换 | H10: 1 | I10: 台架
A11: 4 | B11: 4. 功能设计 | C11: 4.2.2 车控区 | D11: F-快捷入口 | E11: 右上角展示了快捷入口 | F11: 1.打开3D车控区 2.点击快捷功能右上角快捷入口 | G11: 进入车辆设置APP界面 | H11: 1 | I11: 台架
A12: 5 | B12: 4. 功能设计 | C12: 4.2.2 车控区 | D12: F-天窗快捷设置 | E12: 快捷设置界面-天窗控制 | F12: 选择开启/通风/关闭 | G12: 选择开启：打开天窗 选择通风：打开天窗通风模式 选择关闭：关闭天窗 | H12: 1 | I12: 台架
A13: 6 | B13: 4. 功能设计 | C13: 4.2.2 车控区 | D13: F-陡坡缓降快捷设置 | E13: 快捷设置界面-陡坡缓降 | F13: 点击开关 | G13: 开启了陡坡缓降功能，再次点击关闭 | H13: 1 | I13: 台架
A14: 7 | B14: 4. 功能设计 | C14: 4.2.2 车控区 | D14: F-转向助力快捷设置 | E14: 快捷设置界面-转向助力 | F14: 点击选择标准/轻/重 | G14: 选择标准：车辆转向助力为标准 选择轻：车辆转向助力为轻 选择重：车辆转向助力为重 | H14: 1 | I14: 台架
A15: 8 | B15: 4. 功能设计 | C15: 4.2.2 车控区 | D15: F-大灯高度快捷设置 | E15: 快捷设置界面-大灯高度 | F15: 右滑动控制条至10 | G15: 页面大灯高度数值展示：10 | H15: 1 | I15: 台架
A16: 9 | B16: 4. 功能设计 | C16: 4.2.2 车控区 | D16: F-自动远光灯快捷设置 | E16: 快捷设置界面-自动远光灯 | F16: 点击开关 | G16: 打开自动远光灯功能，再次点击关闭 | H16: 1 | I16: 台架
A17: 10 | B17: 4. 功能设计 | C17: 4.2.2 车控区 | D17: F-前照灯延时快捷设置 | E17: 快捷设置界面-前照灯延时 | F17: 下拉框选择60S | G17: 前照灯延时时间为60S | H17: 1 | I17: 台架
A18: 11 | B18: 4. 功能设计 | C18: 4.2.2 车控区 | D18: F-遥控泊车行驶最大距离快捷设置 | E18: 快捷设置界面-遥控泊车行驶最大距离 | F18: 左滑动控制条至1M | G18: 遥控泊车行驶最大距离为1M | H18: 1 | I18: 台架
A19: 12 | B19: 4. 功能设计 | C19: 4.2.2 车控区 | D19: F-并线辅助快捷设置 | E19: 快捷设置界面-并线辅助 | F19: 点击开关 | G19: 开启并线辅助功能，再次点击关闭 | H19: 1 | I19: 台架
... A37: 30 | B37: 4. 功能设计 | C37: 4.3.2 维修保养区 | D37: F-网点查询展示逻辑 | E37: 网点查询弹窗页面 | F37: 页面展示 | G37: 长安4s店信息展示在最前面，距离由近到远展示 | H37: 2 | I37: 台架

Sheet 导航主页
A1: 总用例 | B1: 84 | C1: XXX零部件测试导航主页用例
A2: passed | B2: =COUNTIF(J:J,"=passed") -> 0
A3: failed | B3: =COUNTIF(J:J,"=failed") -> 0
A4: blocked | B4: =COUNTIF(J:J,"=blocked") -> 0
A5: N/A | B5: =COUNTIF(J:J,"=N/A") -> 0
A6: 项目名称：XXX | C6: 版本: | E6: 编制: | G6: 测试人员: | I6: 测试日期:
A7: 用例序号 | B7: 所属模块 | C7: 相关需求 | D7: 用例标题 | E7: 前置条件 | F7: 步骤 | G7: 预期 | H7: 优先级 | I7: 用例执行方式 | J7: 用例执行结果 | K7: DTM缺陷号
A8: 1 | B8: 导航主页 | C8: 无 | D8: F-dock栏固定排序为AI主页、地图主页、娱乐主页、车主页、全量应用 | E8: 主界面页面 | F8: 1. 查看dock栏按键 | G8: 1. 固定排序为AI主页、地图主页、娱乐主页、车主页、全量应用 | H8: 2 | I8: 台架
A9: 2 | B9: 导航主页 | C9: 无 | D9: S-点击dock栏对应按钮，可进入对应的主页。选中项需高亮。 | E9: 主界面页面 | F9: 1. 点击dock栏各个按键 | G9: 1. 可进入对应的主页。选中项需高亮。 | H9: 2 | I9: 台架
A10: 3 | B10: 导航主页 | C10: 无 | D10: S-频繁切换dock栏图标，可以正常响应，无卡滞错乱现象。 | E10: 主界面页面 | F10: 1. 频繁切换dock栏图标 | G10: 1. 正常响应，无卡滞错乱现象。 | H10: 1 | I10: 台架
A11: 4 | B11: 导航主页 | C11: 无 | D11: F-首次开机默认AI主页（首次开机/软件升级更新后初次开机/恢复出厂设置三种场景） | E11: 电源ON档，HU处于工作状态 | F11: 1. 首次开机查看主界面 2. 软件升级升级后首次进入查看主界面 3.恢复出厂设置后进入查看主界面 | G11: 1. 默认都是AI主页界面 | H11: 2 | I11: 台架
A12: 5 | B12: 导航主页 | C12: 无 | D12: S-设置地图主页为开机主页，重启后开机显示为地图主页 | E12: AI主页界面 | F12: 1. 点击地图按键 2. 关机重启 3.查看主界面 | G12: 1. 重启后显示为地图主页 | H12: 1 | I12: 台架
A13: 6 | B13: 导航主页 | C13: 无 | D13: S-设置娱乐主页为开机主页，重启后开机显示为娱乐主页 | E13: AI主页界面 | F13: 1. 点击娱乐按键 2. 关机重启 3.查看主界面 | G13: 1. 重启后显示为娱乐主页 | H13: 2 | I13: 台架
A14: 7 | B14: 导航主页 | C14: 无 | D14: S-设置车主页为开机主页，重启后开机显示为车主页 | E14: AI主页界面 | F14: 1. 点击车主页按键 2. 关机重启 3.查看主界面 | G14: 1. 重启后显示为车主页 | H14: 2 | I14: 台架
A15: 8 | B15: 导航主页 | C15: 无 | D15: S-设置全量应用为开机主页，重启后开机显示为全量应用 | E15: AI主页界面 | F15: 1. 点击全量应用按键 2. 关机重启 3.查看主界面 | G15: 1. 重启后显示为全量应用主页 | H15: 2 | I15: 台架
A16: 9 | B16: 导航主页 | C16: 无 | D16: S-dock栏左下角显示时间及星期 | E16: AI主页界面 | F16: 1. 查看dock栏左下角显示 | G16: 1. 显示实时时间及星期 | H16: 2 | I16: 台架
A17: 10 | B17: 导航主页 | C17: 无 | D17: F-点击DOCK栏导航图标，进入导航主页 | E17: AI主页界面 | F17: 1. 点击DOCK栏导航图标 | G17: 1. 显示导航主页界面 | H17: 1 | I17: 台架
A18: 11 | B18: 导航主页 | C18: 无 | D18: F-导航主页面左上角显示语音交互区：包括语音助手形象、语音提示区、语音打字机三个部分.文字显示：你可以说"小安你好" | E18: 导航主页界面 | F18: 1. 查看界面布局 | G18: 1. 导航主页面左上角显示语音交互区：包括语音助手形象、语音提示区、语音打字机三个部分.文字显示：你可以说"小安你好" | H18: 1 | I18: 台架
A19: 12 | B19: 导航主页 | C19: 无 | D19: F-显示长安语助形象，点击唤醒。 | E19: 导航主页界面 | F19: 1. 点击长安语助形象 | G19: 1. 可唤醒语音助手 | H19: 1 | I19: 台架
... A91: 84 | B91: 导航主页 | C91: 无 | D91: F-点击空调状态信息各个图标，可进入空调设置界面。 | E91: 导航主页界面 | F91: 1. 点击空调状态信息各个图标 | G91: 1. 可进入空调设置界面 | H91: 2 | I91: 台架

Sheet 高德地图
A1: 总用例 | B1: 191 | C1: XXX零部件测试高德地图用例
A2: passed | B2: =COUNTIF(J:J,"=passed") -> 0
A3: failed | B3: =COUNTIF(J:J,"=failed") -> 0
A4: blocked | B4: =COUNTIF(J:J,"=blocked") -> 0
A5: N/A | B5: =COUNTIF(J:J,"=N/A") -> 0
A6: 项目名称：XXX | C6: 版本: | E6: 编制: | G6: 测试人员: | I6: 测试日期:
A7: 用例序号 | B7: 所属模块 | C7: 相关需求 | D7: 用例标题 | E7: 前置条件 | F7: 步骤 | G7: 预期 | H7: 优先级 | I7: 用例执行方式 | J7: 用例执行结果 | K7: DTM缺陷号
A8: 1 | B8: 高德地图 | C8: 高德地图登录界面 | D8: F-高德地图进入 | E8: 有网络 | F8: 点击屏幕高德图标进入 | G8: 弹出使用提示弹框 | H8: 1 | I8: 台架
A9: 2 | B9: 高德地图 | C9: 高德地图登录界面 | D9: F-高德地图返回 | E9: 有网络 | F9: 点击屏幕主页图标 | G9: 退出地图界面 | I9: 台架
A10: 3 | B10: 高德地图 | C10: 高德地图登录界面 | D10: F-高德地图登录界面 | E10: 有网络 | F10: 点击地图左上角图标 | G10: 进入登录界面 | I10: 台架
A11: 4 | B11: 高德地图 | C11: 高德地图登录界面 | D11: F-高德地图扫码 | E11: 有网络 | F11: 扫描登录，手机端打开高德扫描车机上二维码框 | G11: 登录成功 | I11: 台架
A12: 5 | B12: 高德地图 | C12: 高德地图登录界面 | D12: F-高德地图注册 | E12: 有网络 | F12: 注册 | G12: 出现手机号码输入界面，数字键盘 | I12: 台架
A13: 6 | B13: 高德地图 | C13: 高德地图登录界面 | D13: F-高德地图验证码 | E13: 有网络 | F13: 验证码登录 | G13: 输入手机号码，点击获取验证码 | I13: 台架
A14: 7 | B14: 高德地图 | C14: 高德地图登录界面 | D14: F-高德地图登录信息 | E14: 登录成功 | F14: 打开登录界面 | G14: 正常显示登录的账号头像，名称，里程，消息等 | I14: 台架
A15: 8 | B15: 高德地图 | C15: 高德地图登录界面 | D15: F-高德地图退出登录 | E15: 登录成功 | F15: 点击登录成功界面右上角图标退出登录 | G15: 退出登录成功 | I15: 台架
A16: 9 | B16: 高德地图 | C16: 高德地图登录界面 | D16: F-高德地图共享位置 | E16: 登录界面 | F16: 我的消息 | G16: 显示手机端发送的共享位置信息 | I16: 台架
A17: 10 | B17: 高德地图 | C17: 高德地图登录界面 | D17: F-高德地图广播消息 | E17: 登录界面 | F17: 广播消息 | G17: 高德公司发送的消息显示在此栏，如果没有则为空 | I17: 台架
A18: 11 | B18: 高德地图 | C18: 高德地图登录界面 | D18: F-高德地图显示行程 | E18: 自动行程功能开启 | F18: 我的行程 | G18: 显示经历过的导航+巡航里程，进入后显示行程总里程，行程条数，行程同步的日期 | I18: 台架
A19: 12 | B19: 高德地图 | C19: 高德地图登录界面 | D19: F-高德地图下载行程 | E19: 自动行程功能开启 | F19: 下载行程 | G19: 点击行程可以正常下载，地图显示行程路线 | I19: 台架
A20: 13 | B20: 高德地图 | C20: 高德地图登录界面 | D20: F-高德地图删除行程 | E20: 自动行程功能开启 | F20: 删除行程 | G20: 点击行程详情右边显示回收站图标，可以正常删除行程 | I20: 台架
... A171: 164 | B171: 高德地图 | C171: 高德地图语音选点导航 | D171: F-高德地图放大比例 | E171: 地图界面 | F171: 放大地图比例到最大比例 | G171: 音乐控制缩放有提示音“已是最大比例尺”，手指点触地图放大地图正常，最大后【+】灰显 | I171: 台架
A172: 165 | B172: 高德地图 | C172: 高德地图语音选点导航 | D172: F-高德地图背景导航 | E172: 背景导航 | G172: 回到主页，仍然可以显示导航，屏幕下部显示提示路线已更新等提示信息 | I172: 台架
A173: 166 | B173: 高德地图 | C173: 高德地图语音选点导航 | D173: F-高德地图分享导航 | E173: 分享导航 | G173: 导航完成后，地图右下部有个分享导航图标，有个类似下载的箭头 | I173: 台架
A174: 167 | B174: 高德地图 | C174: 高德地图定位 | D174: F-高德地图GPS未连接测试 | E174: GPS没有连接，连接wifi | F174: 主图显示蓝色小圆点，断开wifi | G174: 车边变成灰色 | I174: 实车
A175: 168 | B175: 高德地图 | C175: 高德地图定位 | D175: F-高德地图开启导航 | E175: 正常开启导航 | F175: 导航主图状态下 | G175: 不会出现低油量弹条 | I175: 台架
A176: 169 | B176: 高德地图 | C176: 高德地图定位 | D176: F-高德地图显示卫星数量 | E176: 正常显示卫星数量 | F176: 进入地图界面 | G176: 地图状态栏显示卫星数量 | I176: 台架
A177: 170 | B177: 高德地图 | C177: 高德地图定位 | D177: F-高德地图语音爆破音测试 | E177: 背景播放本地音乐（或者FM） | F177: 进入地图界面，语音：“我在哪里”播报位置前有一个爆破音 | G177: 不出现爆破音 | I177: 台架
A178: 171 | B178: 高德地图 | C178: 高德地图定位 | D178: F-高德地图模拟导航不卡死 | E178: 地图界面 | F178: 开始模拟导航 | G178: 正常模拟导航等不出现卡死等 | I178: 台架
A179: 172 | B179: 高德地图 | C179: 高德地图定位 | D179: F-高德地图模拟导航偏好 | E179: 进入地图界面 | F179: 选择任意地点进行模拟导航，进入设置，选择加油站偏好，搜索的结果偏好设置没有显示在前面 | G179: 搜索结果正常显示 | I179: 台架
A180: 173 | B180: 高德地图 | C180: 高德地图定位 | D180: F-高德地图集结 | E180: 进入地图界面 | F180: 地图页面打开集结，设置我的昵称，输入框光标未显示在名称后面 | G180: 昵称输入界面正常 | I180: 台架
A181: 174 | B181: 高德地图 | C181: 高德地图定位 | D181: F-高德地图创建队伍 | E181: 进入地图界面 | F181: 创建我的队伍（此时是灰色状态）进入后，提示已经在队伍中 | G181: 正常创建队伍，在线，离线状态正常 | I181: 台架
A182: 175 | B182: 高德地图 | C182: 高德地图定位 | D182: F-高德地图手机互联 | E182: 进入地图界面 | F182: 手机高德扫描进行车机互联成功，车辆行驶后，车机跟手机自动断开连接 | G182: 正常显示连接或者断开状态 | I182: 台架
A183: 176 | B183: 高德地图 | C183: 高德地图定位 | D183: F-高德地图附近目的地导航 | E183: 实车导航 | F183: 附近的目的地导航后，目的地图标处显示 | G183: 目的地正常显示 | I183: 实车
A184: 177 | B184: 高德地图 | C184: 高德地图定位 | D184: F-高德地图收藏夹 | E184: 进入地图界面 | F184: 地图左上角菜单栏，重命名收藏地点后，新地址名称查看周边，搜索栏还是显示重命名前的地址 | G184: 正常显示名称 | I184: 台架
A185: 178 | B185: 高德地图 | C185: 高德地图定位 | D185: F-高德地图导航音量 | E185: 进入地图界面 | F185: 手机高德扫描或者手机号码验证码登录后导航播报音变成10，系统导航音量为1 | G185: 登录前后，播报音量一致 | I185: 台架
... A198: 191 | B198: 高德地图 | C198: 高德地图定位 | D198: F-高德地图与mode键交互 | E198: 进入地图界面 | F198: 按mode键切源 | G198: 切换正常，地图保持后台运行 | I198: 实车

Sheet 状态栏(底部状态栏)
A1: 总用例 | B1: 66 | C1: XXX零部件测试状态栏用例
A2: passed | B2: =COUNTIF(J:J,"=passed") -> 0
A3: failed | B3: =COUNTIF(J:J,"=failed") -> 0
A4: blocked | B4: =COUNTIF(J:J,"=blocked") -> 0
A5: N/A | B5: =COUNTIF(J:J,"=N/A") -> 0
A6: 项目名称：XXX | C6: 版本: | E6: 编制: | G6: 测试人员: | I6: 测试日期:
A7: 用例序号 | B7: 所属模块 | C7: 相关需求 | D7: 用例标题 | E7: 前置条件 | F7: 步骤 | G7: 预期 | H7: 优先级 | I7: 用例执行方式 | J7: 用例执行结果 | K7: DTM缺陷号
A8: 1 | B8: 状态栏 | C8: 1.布局定义 | D8: F-主页打开下拉菜单 | E8: / | F8: 1.打开主页 2.从屏幕顶部向下滑动 | G8: 显示下拉菜单 | H8: 1 | I8: 台架
A9: 2 | B9: 状态栏 | C9: 1.布局定义 | D9: F-导航页打开下拉菜单 | E9: / | F9: 1.打开导航页面 2.从屏幕顶部向下滑动 | G9: 显示下拉菜单 | H9: 2 | I9: 台架
A10: 3 | B10: 状态栏 | C10: 1.布局定义 | D10: F-多媒体页打开下拉菜单 | E10: / | F10: 1.打开多媒体页面 2.从屏幕顶部向下滑动 | G10: 显示下拉菜单 | H10: 1 | I10: 台架
A11: 4 | B11: 状态栏 | C11: 1.布局定义 | D11: F-车主页页打开下拉菜单 | E11: / | F11: 1.打开车主页页面 2.从屏幕顶部向下滑动 | G11: 显示下拉菜单 | H11: 2 | I11: 台架
A12: 5 | B12: 状态栏 | C12: 1.布局定义 | D12: F-全量应用页打开下拉菜单 | E12: / | F12: 1.打开全量应用页面 2.从屏幕顶部向下滑动 | G12: 显示下拉菜单 | H12: 2 | I12: 台架
A13: 6 | B13: 状态栏 | C13: 蓝牙图标 | D13: F-蓝牙图标高亮显示 | E13: 蓝牙已打开 | F13: 1.打开下拉菜单引导区 2.查看蓝牙图标展示 | G13: 蓝牙功能打开，蓝牙图标高亮显示 | H13: 2 | I13: 台架
A14: 7 | B14: 状态栏 | C14: 蓝牙图标 | D14: F-蓝牙图标置灰 | E14: 蓝牙已关闭 | F14: 1.打开下拉菜单引导区 2.查看蓝牙图标展示 | G14: 蓝牙功能关闭，蓝牙图标置灰 | H14: 2 | I14: 台架
A15: 8 | B15: 状态栏 | C15: 蓝牙图标 | D15: F-蓝牙连接时下方文字展示 | E15: 蓝牙连接时 | F15: 1.打开下拉菜单引导区 2.查看蓝牙图标下方展示 | G15: 显示连接设备名称，仅显示一排，字数超过用…表示 | H15: 2 | I15: 台架
A16: 9 | B16: 状态栏 | C16: 蓝牙图标 | D16: F-短按蓝牙图标 | E16: 蓝牙已打开 | F16: 1.打开下拉菜单引导区 2.短按蓝牙图标 | G16: 关闭蓝牙 | H16: 1 | I16: 台架
A17: 10 | B17: 状态栏 | C17: 蓝牙图标 | D17: F-短按蓝牙图标 | E17: 蓝牙已关闭 | F17: 1.打开下拉菜单引导区 2.短按蓝牙图标 | G17: 打开蓝牙 | H17: 1 | I17: 台架
A18: 11 | B18: 状态栏 | C18: 蓝牙图标 | D18: F-长按蓝牙图标 | E18: / | F18: 1.打开下拉菜单引导区 2.长按蓝牙图标 | G18: 1.弹出蓝牙连接悬浮窗 2.下拉菜单同时收起 | H18: 2 | I18: 台架
A19: 12 | B19: 状态栏 | C19: wifi图标 | D19: F-wifi图标高亮显示 | E19: wifi已打开 | F19: 1.打开下拉菜单引导区 2.查看wifi图标展示 | G19: 1.wifi功能打开， 2.wifi图标高亮显示 | H19: 2 | I19: 台架
... A73: 66 | B73: 状态栏 | C73: 空调净化图标 | D73: F-空调空气净化器图标不显示 | E73: 状态栏区域 | F73: 1.在状态栏区域 2.空调净化器关闭后 | G73: 不显示图标 | H73: 1 | I73: 台架

Sheet 文件管理
A1: 总用例 | B1: 144 | C1: XXX零部件测试文件管理用例
A2: passed | B2: =COUNTIF(J:J,"=passed") -> 0
A3: failed | B3: =COUNTIF(J:J,"=failed") -> 0
A4: blocked | B4: =COUNTIF(J:J,"=blocked") -> 0
A5: N/A | B5: =COUNTIF(J:J,"=N/A") -> 0
A6: 项目名称：XXX | C6: 版本: | E6: 编制: | G6: 测试人员: | I6: 测试日期:
A7: 用例序号 | B7: 所属模块 | C7: 相关需求 | D7: 用例标题 | E7: 前置条件 | F7: 步骤 | G7: 预期 | H7: 优先级 | I7: 用例执行方式 | J7: 用例执行结果 | K7: DTM缺陷号
A8: 1 | B8: 文件管理 | C8: USB(I209.01.01.00) | D8: F-识别USB连接 | E8: 插上U盘 | F8: 上电开机进入文件管理 | G8: 页面左侧文件源USB储存可选择 | H8: 1 | I8: 台架
A9: 2 | B9: 文件管理 | C9: USB(I209.01.01.00) | D9: F-未上U盘USB文件源置灰 | E9: 未插U盘 | F9: 上电开机进入文件管理 | G9: 页面USB文件源置灰，不可选择 | H9: 1 | I9: 台架
A10: 3 | B10: 文件管理 | C10: USB(I209.01.01.00) | D10: F-未识别到USB连接 | E10: 插上U盘 | F10: 1.上电开机进入文件管理 2.没有识别到USB | G10: 页面USB文件源置灰，不可选择 | H10: 1 | I10: 台架
A11: 4 | B11: 文件管理 | C11: HDD(I209.01.02.00) | D11: F-首次进入文件管理 | E11: / | F11: 1.首次进入文件管理 | G11: 1.默认进入本地储存 2.HDD文件源一直处于可选状态，不会置灰 | H11: 1 | I11: 台架
A12: 5 | B12: 文件管理 | C12: 音频文件列表(I209.02.01.00) | D12: F-音频列表展示 | E12: 1.进入文件管理 2.选择USB储存 3.打开音频列表 | F12: 1.查看列表展示 2.查看排序逻辑 | G12: 1.音频列表中全部显示音频文件 2.按照系统自身顺序方式排序 | H12: 3 | I12: 台架
A13: 6 | B13: 文件管理 | C13: 音频文件列表(I209.02.01.00) | D13: F-播放的音频文件高亮显示 | E13: 1.进入文件管理 2.选择USB储存 3.打开音频列表 | F13: 1.点击播放音频文件 2.查看播放中的音频文件状态 | G13: 要高亮显示并且显示播放状态图标 | H13: 2 | I13: 台架
A14: 7 | B14: 文件管理 | C14: 音频文件列表(I209.02.01.00) | D14: F-打开音频列表，不进入多媒体应用 | E14: 1.进入文件管理 2.选择USB储存 3.打开音频列表 | F14: 直接点击即可开始播放 | G14: 不进入多媒体应用 | H14: 1 | I14: 台架
A15: 8 | B15: 文件管理 | C15: 音频文件列表(I209.02.01.00) | D15: F-音频播放 | E15: 1.进入文件管理 2.选择USB储存 3.打开音频列表 | F15: 点击正在播放的歌曲 | G15: 取消播放 | H15: 1 | I15: 台架
A16: 9 | B16: 文件管理 | C16: 图片文件列表(I209.02.02.00) | D16: F-图片列表展示 | E16: 1.进入文件管理 2.选择USB储存 3.打开图片列表 | F16: 1.查看列表展示 2.查看排序逻辑 | G16: 1.显示当前文件源下所有的的图片文件 2.按照系统自身顺序方式排序 | H16: 2 | I16: 台架
A17: 10 | B17: 文件管理 | C17: 图片文件列表(I209.02.02.00) | D17: F-高亮显示打开的图片 | E17: 1.进入文件管理 2.选择USB储存 3.打开图片列表 | F17: 点击图片播放 | G17: 当前打开的图片要高亮显示 | H17: 1 | I17: 台架
A18: 11 | B18: 文件管理 | C18: 图片文件列表(I209.02.02.00) | D18: F-图片浏览模式 | E18: 1.进入文件管理 2.选择USB储存 3.打开图片列表 | F18: 可直接点击图片文件 | G18: 进入图片浏览模式 | H18: 1 | I18: 台架
A19: 12 | B19: 文件管理 | C19: 视频文件列表(I209.02.03.00) | D19: F-视频列表展示 | E19: 1.进入文件管理 2.选择USB储存 3.打开视频列表 | F19: 1.查看列表展示 2.查看排序逻辑 | G19: 1.显示当前文件源下所有的的视频文件 2.按照系统自身顺序方式排序 | H19: 3 | I19: 台架
... A151: 144 | B151: 文件管理 | C151: 文件限制条件 | D151: F-无效音频文件扩展名被修改 | E151: 无效音频文件 | F151: 本为BBB.txt，但将其扩展名修改为BBB.m3 | G151: 1.系统能够识别并显示，但不会被正常播放， 2.当播放到该文件时，系统提示“不支持该文件”， 然后跳至下一曲播放 | H151: 1 | I151: 台架

Sheet 自检APP
A1: 总用例 | B1: 24 | C1: XXX零部件测试自检APP用例
A2: passed | B2: =COUNTIF(J:J,"=passed") -> 0
A3: failed | B3: =COUNTIF(J:J,"=failed") -> 0
A4: blocked | B4: =COUNTIF(J:J,"=blocked") -> 0
A5: N/A | B5: =COUNTIF(J:J,"=N/A") -> 0
A6: 项目名称：XXX | C6: 版本: | E6: 编制: | G6: 测试人员: | I6: 测试日期:
A7: 用例序号 | B7: 所属模块 | C7: 相关需求 | D7: 用例标题 | E7: 前置条件 | F7: 步骤 | G7: 预期 | H7: 优先级 | I7: 用例执行方式 | J7: 用例执行结果 | K7: DTM缺陷号
A8: 1 | B8: 自检APP | C8: 自检APP功能说明书-4 THU 自检功能 | D8: F-非运输模式执行自检APP | E8: 1.SIM卡处于非停用状态 2.TBOX处于非运输状态 | F8: 1、操作车机进入工程模式； 2、在车机上点击“自检APP”; | G8: 1、车机APP开始下发自检指令，TBOX接收到HU发送开始自检指令，log为：selfTest https start 2、HU上连通性测试通过，开始下一项测试 | H8: 1 | I8: 仿真
A9: 2 | B9: 自检APP | C9: 自检APP功能说明书-4 THU 自检功能 | D9: F-运输模式执行自检APP | E9: 1.SIM卡处于非停用状态 2.TBOX处于运输状态 | F9: 1、修改redis中transport的值为true; 2、操作车机进入工程模式； 3、在车机上点击“自检APP”; | G9: 1、车机APP开始下发自检指令，TBOX接收到HU发送开始自检指令，log为：selfTest https start 2、HU上连通性测试通过，开始下一项测试 | H9: 2 | I9: 仿真
A10: 3 | B10: 自检APP | C10: 自检APP功能说明书-4 THU 自检功能 | D10: F-车机APP进行网络测试，检测HU的http、HTTPS连通失败 | E10: 1.SIM卡处于非停用状态 2.TBOX处于非运输状态 | F10: 1、点击自检APP的“开始自检”按钮； 2、修改redis数据库中server.conf的URL_TEST的值为错误的,断电重启； | G10: 2.反馈失败原因，结束自检流程（tbox通信） | H10: 1 | I10: 仿真
A11: 4 | B11: 自检APP | C11: 自检APP功能说明书-4 THU 自检功能 | D11: F-车机APP进行网络测试，TCP联通失败 | E11: 1.SIM卡处于非停用状态 2.TBOX处于非运输状态 | F11: 1、使用at指令关闭sim卡信号（at+cfun=0); 2、使用adb线，连接车机，打开车机，点击车机自检APP; | G11: TCP连接失败（tbox通信） | H11: 1 | I11: 仿真
A12: 5 | B12: 自检APP | C12: 自检APP功能说明书-4 THU 自检功能 | D12: F-取掉usb后进行自检 | E12: 1.SIM卡处于非停用状态 2.TBOX处于非运输状态 | F12: 1、取掉usb，断电重启 2、进入tbox自检界面（自带刷新） | G12: 1、车机APP显示无网络； 2、APP页面右下侧按钮不可点击，显示提示“获取信息失败，请检查并退出重试”； | H12: 1 | I12: 仿真
A13: 6 | B13: 自检APP | C13: 自检APP功能说明书-4 THU 自检功能 | D13: F-TBOX certid信息为错误信息时执行自检APP | E13: 1.SIM卡处于非停用状态 2.TBOX处于非运输状态 | F13: 1、修改terminal.conf配置文件中CertId为错误的值 2、删除redis中的REDIS_LOAD完成配置文件更新; 3、断电重启 4、操作车机进入工程模式； 5、在车机上点击“自检APP”; | G13: 5、HU反馈失败原因，结束自检流程（数据校验失败） | H13: 1 | I13: 仿真
A14: 7 | B14: 自检APP | C14: 自检APP功能说明书-4 THU 自检功能 | D14: F-ICCID错误时自检 | E14: 1.SIM卡处于非停用状态 2.TBOX处于非运输状态 | F14: 1、修改terminal.conf配置文件中ICCID为错误的值 2、删除redis中的REDIS_LOAD完成配置文件更新; 3、断电重启 4、操作车机进入工程模式； 5、在车机上点击“自检APP”; | G14: 5、HU反馈失败原因，结束自检流程（数据校验失败） | H14: 1 | I14: 仿真
A15: 8 | B15: 自检APP | C15: 自检APP功能说明书-4 THU 自检功能 | D15: F-TUID错误时自检 | E15: 1.SIM卡处于非停用状态 2.TBOX处于非运输状态 | F15: 1、修改terminal.conf配置文件中TUID为错误的值 2、删除redis中的REDIS_LOAD完成配置文件更新; 3、断电重启 4、操作车机进入工程模式； 5、在车机上点击“自检APP”; | G15: 5、HU反馈失败原因，结束自检流程（数据校验失败） | H15: 1 | I15: 仿真
A16: 9 | B16: 自检APP | C16: 自检APP功能说明书-4 THU 自检功能 | D16: F-获取信息成功，点击APP“开始自检自检”成功 | E16: 1.SIM卡处于非停用状态 2.TBOX处于非运输状态 | F16: 1、点击APP“开始自检”按钮； | G16: 1、右下角按钮不可点击，显示“检测中” 2、检测通过图标中自动打钩； | H16: 1 | I16: 仿真
A17: 10 | B17: 自检APP | C17: 自检APP功能说明书-4 THU 自检功能 | D17: F-连通性测试失败 | E17: 1.SIM卡处于非停用状态 2.TBOX处于非运输状态 | F17: 1、在自检APP成功执行之后，断开usb连接线; 2、重新点击自检APP; | G17: 1、APP显示“hu连通性”测试失败； | H17: 2 | I17: 仿真
A18: 11 | B18: 自检APP | C18: 自检APP功能说明书-4 THU 自检功能 | D18: F-数据网络测试通过，证书加密通道测试失败 | E18: 1.SIM卡处于非停用状态 2.TBOX处于非运输状态 | F18: 1、修改redis中证书id,使用错误加密证书 | G18: 1、APP显示证书加密通道测试“无法建立连接"； 2、后面项目直接显示失败，不显示失败原因； | H18: 2 | I18: 仿真
A19: 12 | B19: 自检APP | C19: 自检APP功能说明书-4 THU 自检功能 | D19: F-自检，远程控制（闪灯、鸣笛）失败 | E19: 1.SIM卡处于非停用状态 2.TBOX处于非运输状态 | F19: 1、点击车机APP自检按钮； 2、测试进入远程闪灯鸣笛； 3、下发远程控制闪灯鸣笛请求； 4、不回复远程控制CAN信号 | G19: 1、APP远程控制鸣笛显示“指令执行超时”； 2、APP页面右下侧显示信息是一致的，检测失败，请点击重试； | H19: 1 | I19: 仿真
... A31: 24 | B31: 自检APP | C31: 自检APP功能说明书-4 THU 自检功能 | D31: F-无网络条件执行自检APP | E31: 1.SIM卡处于非停用状态 2.TBOX处于非运输状态 | F31: 1、tbox的网络情况在无网络情况下 2、点击APP“开始自检”按钮； | G31: 1、自检失败反馈失败选项 | H31: 1 | I31: 仿真

Sheet 蓝牙电话
A1: 总用例 | B1: 191 | C1: XXX零部件测试蓝牙电话用例
A2: passed | B2: =COUNTIF(J:J,"=passed") -> 0
A3: failed | B3: =COUNTIF(J:J,"=failed") -> 0
A4: blocked | B4: =COUNTIF(J:J,"=blocked") -> 0
A5: N/A | B5: =COUNTIF(J:J,"=N/A") -> 0
A6: 项目名称：XXX | C6: 版本: | E6: 编制: | G6: 测试人员: | I6: 测试日期:
A7: 用例序号 | B7: 所属模块 | C7: 相关需求 | D7: 用例标题 | E7: 前置条件 | F7: 步骤 | G7: 预期 | H7: 优先级 | I7: 台架 | J7: 用例执行结果 | K7: DTM缺陷号
A8: 1 | B8: 蓝牙电话 | C8: I208BT电话需求规格说明书-V4.0-2.7.1 操作性能指标 | D8: F-BT开启-所需时间 | E8: BT电话app能打开且能使用 | F8: 1. 打开BT电话app 2. 开启BT开关 3.查看开启所需的时间 | G8: 1. 所需时间≤500ms | H8: 2
A9: 2 | B9: 蓝牙电话 | C9: I208BT电话需求规格说明书-V4.0-2.7.1 操作性能指标 | D9: F-BT开启-成功率 | E9: BT电话app能打开且能使用 | F9: 1. 打开BT电话app 2. 开启BT开关 3.查看是否能开启 | G9: 1. 成功率100% | H9: 2
A10: 3 | B10: 蓝牙电话 | C10: I208BT电话需求规格说明书-V4.0-2.7.1 操作性能指标 | D10: F-BT设备搜 索所需时间 | E10: BT已开启 | F10: 1. 开启BT设备（车端、手机端） 2. 查看搜索设备所需时间 | G10: 1. 所需时间≤3s | H10: 2
A11: 4 | B11: 蓝牙电话 | C11: I208BT电话需求规格说明书-V4.0-2.7.1 操作性能指标 | D11: F-车端BT搜索手机端成功率 | E11: BT已开启 | F11: 1. 开启BT设备（车端、手机端） 2. 查看车端是否能搜索到手机端的BT | G11: 1. 成功率100% | H11: 2
A12: 5 | B12: 蓝牙电话 | C12: I208BT电话需求规格说明书-V4.0-2.7.1 操作性能指标 | D12: F-手机端BT搜索车端成功率 | E12: BT已开启 | F12: 1. 开启BT设备（车端、手机端） 2. 查看手机端是否能搜索到车端的BT | G12: 1. 成功率100% | H12: 2
A13: 6 | B13: 蓝牙电话 | C13: I208BT电话需求规格说明书-V4.0-2.7.1 操作性能指标 | D13: F-BT配对成功所需时间 | E13: 1.BT已开启 2.能搜索到设备 | F13: 1. 开启BT设备（车端、手机端） 2. 点击设备进行配对 | G13: 1. 所需时间≤4s | H13: 2
A14: 7 | B14: 蓝牙电话 | C14: I208BT电话需求规格说明书-V4.0-2.7.1 操作性能指标 | D14: F-BT配对成功率 | E14: 1.BT已开启 2.能搜索到设备 | F14: 1. 开启BT设备（车端、手机端） 2. 点击设备进行配对 | G14: 1. 成功率100% | H14: 2
A15: 8 | B15: 蓝牙电话 | C15: I208BT电话需求规格说明书-V4.0-2.7.1 操作性能指标 | D15: F-BT自动连接所需时间 | E15: 非首次连接 | F15: 1.开启已配对成功且已连接成功的手机和车的BT 2.查看是否能自动连接，以及连接所需时间 | G15: 1. 所需时间≤2s | H15: 2
A16: 9 | B16: 蓝牙电话 | C16: I208BT电话需求规格说明书-V4.0-2.7.1 操作性能指标 | D16: F-BT自动连接成功率 | E16: 非首次连接 | F16: 1.开启已配对成功且已连接成功的手机和车的BT 2.查看是否能自动连接成功 | G16: 1. 成功率100% | H16: 2
A17: 10 | B17: 蓝牙电话 | C17: I208BT电话需求规格说明书-V4.0-2.7.1 操作性能指标 | D17: F-BT断开所需时间 | E17: BT设备已连接 | F17: 1、点击已连接的手机设备，在弹出框确认断开BT 2.查看断开所需时间 | G17: 1. 所需时间≤1s | H17: 2
A18: 11 | B18: 蓝牙电话 | C18: I208BT电话需求规格说明书-V4.0-2.7.1 操作性能指标 | D18: F-BT关闭所需时间 | E18: BT已开启 | F18: 1. 关闭BT启动开关 2.查看关闭所需时间 | G18: 1. 所需时间≤500ms | H18: 2
A19: 12 | B19: 蓝牙电话 | C19: I208BT电话需求规格说明书-V4.0-2.7.1 操作性能指标 | D19: F-BT关闭成功率 | E19: BT已开启 | F19: 1. 关闭BT启动开关 2.查看是否能关闭 | G19: 1. 成功率100% | H19: 2
... A198: 191 | B198: 蓝牙电话 | C198: I208BT电话需求规格说明书-V4.0-3.4 通话3.4.6 通话记录3.4.6.1 更新 | D198: F-实时在车机端的通话记录进行更新保存 | E198: 1.BT已连接 2.同步联系人开启 | F198: 1.手机端修改联系人名称 婷婷 157178989876 修改为 婷鑫微 157178989876 | G198: 1.修改信息实时在车机端的 通话记录中进行更新保存，车机端显示 婷鑫微 157178989876 | H198: 2

Sheet 鉴权
A1: 总用例 | B1: 26 | C1: XXX零部件测试鉴权用例
A2: passed | B2: =COUNTIF(J:J,"=passed") -> 0
A3: failed | B3: =COUNTIF(J:J,"=failed") -> 0
A4: blocked | B4: =COUNTIF(J:J,"=blocked") -> 0
A5: N/A | B5: =COUNTIF(J:J,"=N/A") -> 0
A6: 项目名称：XXX | C6: 版本: | E6: 编制: | G6: 测试人员: | I6: 测试日期:
A7: 用例序号 | B7: 所属模块 | C7: 相关需求 | D7: 用例标题 | E7: 前置条件 | F7: 步骤 | G7: 预期 | H7: 优先级 | I7: 用例执行方式 | J7: 用例执行结果 | K7: DTM缺陷号
A8: 1 | B8: 车机鉴权 | C8: 车机鉴权规范-V1.6.5-车机系统鉴权 | D8: F-车机系统鉴权基础功能(wifi未连接状态) | E8: 车机启动状态，预生产环境备案ok，wifi未连接 | F8: 1.车机启动开机； 2.使用酷我/喜马拉雅/wifi热点/服务商城/b-CALL/i-CALL/组队出行功能 | G8: 1-2.车联网功能能够正常使用 | H8: 1
A9: 2 | B9: 车机鉴权 | C9: 车机鉴权规范-V1.6.5-车机系统鉴权 | D9: F-车机系统鉴权基础功能(wifi连接状态) | E9: 车机启动状态，预生产环境备案ok，wifi连接 | F9: 1.将车机切换为飞行模式（工程模式切换） 2.关闭车机后重启车机 3.使用酷我/喜马拉雅/WiFi热点/服务商城/b-CALL/i-CALL/组队出行功能 | G9: 3.车联网功能能够正常使用 | H9: 1
A10: 3 | B10: 车机鉴权 | C10: 车机鉴权规范-V1.6.5-车机系统鉴权 | D10: F-车机系统鉴权失败系统不提示开机鉴权 | E10: 车机启动状态，预生产环境备案ok，wifi未连接 | F10: 1.将车机切换为正式环境 2.重启车机 3.观察车机有无鉴权弹窗 | G10: 3.无鉴权弹窗 | H10: 3
A11: 4 | B11: 车机鉴权 | C11: 车机鉴权规范-V1.6.5-车机系统鉴权 | D11: F-车机系统鉴权失败系统不提示token过期自动登录 | E11: 车机启动状态，预生产环境备案ok，wifi未连接 | F11: 1.车机启动开机，打开酷我/喜马拉雅； 2. 将车机切换为正式环境，界面停留在桌面保持12分钟； | G11: 1.酷我/喜马拉雅可以正常使用； 2.无鉴权弹窗 | H11: 3
A12: 5 | B12: 车机鉴权 | C12: 车机鉴权规范-V1.6.5-车机系统鉴权 | D12: F-车机系统鉴权失败系统不提示外部网络从无到有 | E12: 车机启动状态，预生产环境备案ok，wifi未连接 | F12: 1.将车辆驾驶到无网络信号的区域 2.ACC OFF后等待整车休眠 3.ACC ON,车机启动，进入到网络信号正常区域 4.观察车机有无鉴权弹窗 | G12: 4.无鉴权弹窗 | H12: 3
A13: 6 | B13: 车机鉴权 | C13: 车机鉴权规范-V1.6.5-车机系统鉴权 | D13: S-车机系统鉴权失败系统提示D01场景 | E13: 车机启动状态，预生产环境备案ok，wifi未连接 | F13: 1.将车机切换为正式环境 2.重启车机 3.点击酷我/喜马拉雅/wifi热点/服务商城/b-CALL/i-CALL/组队出行功能 4.观察车机有无鉴权弹窗 | G13: 4.弹窗显示“D01:车机系统与平台连接失败” | H13: 2
A14: 7 | B14: 车机鉴权 | C14: 车机鉴权规范-V1.6.5-车机系统鉴权 | D14: S-车机系统鉴权失败系统提示D01场景弹框处理 | E14: 车机启动状态，预生产环境备案ok，wifi未连接 车机无酷我音乐，则应用更换为喜马拉雅 | F14: 1.将车机切换为正式环境 2.重启车机 3.点击酷我音乐 4.在鉴权弹窗“D01:车机系统与平台连接失败”界面点击取消 5.再次点击酷我音乐 6.在弹窗界面，不操作任何按键 7.再次点击酷我，在鉴权弹窗“D01:车机系统与平台连接失败”界面点击重试 8.到工程模式切换为预生产环境 9.回到主页点击酷我 | G14: 4.界面不显示 6.界面无操作5秒后弹窗自动关闭 7.界面仍显示“D01:车机系统与平台连接失败” 9.酷我音乐能够正常使用 | H14: 3
A15: 8 | B15: 车机鉴权 | C15: 车机鉴权规范-V1.6.5-车机系统鉴权 | D15: S-车机系统鉴权失败系统提示D02场景 | E15: 车机启动状态，预生产环境备案ok | F15: 1.车联网同事配合将此设备的基础服务状态修改为其它随机数（不是active inactive pause即可） 2.打开车机，使用酷我/喜马拉雅 3.出现弹框后点击：知道了 | G15: 2.出现D02提示框“车联网基础服务获取失败，请致电呼叫中心400-888-6677” 3.可以退出弹框 | H15: 2
A16: 9 | B16: 车机鉴权 | C16: 车机鉴权规范-V1.6.5-车机系统鉴权 | D16: S-车机系统鉴权失败系统提示W01场景 | E16: 车机启动状态，预生产环境备案ok，wifi未连接 | F16: 1.将车辆行驶到无信号的区域 2.在无信号区域，反复使用酷我/喜马拉雅/wifi热点/服务商城/组队出行功能 3.观察鉴权弹窗 4.10分钟后，驾驶车辆到有信号的区域 5.再使用酷我/喜马拉雅/wifi热点/服务商城/组队出行功能 | G16: 3、对应的功能不能使用，界面显示“W01网络请求超时” 5、对应车联网相关功能能够正常使用 | H16: 3
A17: 10 | B17: 车机鉴权 | C17: 车机鉴权规范-V1.6.5-车机系统鉴权 | D17: S-车机系统鉴权失败系统提示W01场景弹框处理 | E17: 车机启动状态，预生产环境备案ok，wifi未连接 车机无酷我音乐，则应用更换为喜马拉雅 | F17: 1.将车辆行驶到无信号的区域，使用酷我音乐功能 2.在鉴权弹窗“W01:网络请求超时”界面点击取消 3.再次点击酷我音乐功能，在鉴权弹窗“W01:网络请求超时”界面点击重试 | G17: 1.界面显示：W01网络请求超时； 2.取消后弹窗正常关闭； 3.重新点击酷我音乐再次出现鉴权失败提示，W01网络请求超时，点击重试后，界面仍然显示如此； | H17: 3
A18: 11 | B18: 车机鉴权 | C18: 车机鉴权规范-V1.6.5-车机系统鉴权 | D18: S-车机系统鉴权失败系统提示J01场景(wifi未连接状态) | E18: 未进行实名认证的车机，车机启动状态，wifi未连接 | F18: 1.点击使用使用酷我/喜马拉雅/wifi热点/服务商城/b-CALL/i-CALL/组队出行功能 2.观察鉴权弹窗 3.出现弹框点击：知道了 | G18: 1-2.对应的功能不能使用，界面显示“J01您尚未实名认证，车联网基础服务无法使用…….” 3.可以退出弹框 | H18: 3
A19: 12 | B19: 车机鉴权 | C19: 车机鉴权规范-V1.6.5-车机系统鉴权 | D19: S-车机系统鉴权失败系统提示J01场景(wifi连接状态) | E19: 未进行实名认证的车机，车机启动状态，wifi连接 | F19: 1.将车机切换为飞行模式（工程模式切换） 2.关闭车机后重启车机 3.使用酷我/喜马拉雅/移动数据开关/服务商城/BCALL/ECALL等功能 4.出现弹框点击：知道了 | G19: 1-3.对应的功能不能使用，界面显示“J01您尚未实名认证，车联网基础服务无法使用…….” 4.可以退出弹框 | H19: 3
... A33: 26 | B33: 车机鉴权 | C33: 车机鉴权规范-V1.6.5-消息中心 | D33: S-消息中心消息存储与清空 | E33: 车机启动状态，预生产环境备案ok | F33: 1.通过云平台推送给该车机120条消息； 2.在消息底部点击清空全部消息； 3.车机主动向云平台获取5条车机相关消息； | G33: 1.可以成功收到云平台推送消息，超过100条后最先收到的消息被默认删掉； 2.清空全部消息； 3.可以再次收到车机消息； | H33: 3

Sheet 双屏互动
A1: 总用例 | B1: 196 | C1: XXX零部件测试双屏互动用例
A2: passed | B2: =COUNTIF(J:J,"=passed") -> 0
A3: failed | B3: =COUNTIF(J:J,"=failed") -> 0
A4: blocked | B4: =COUNTIF(J:J,"=blocked") -> 0
A5: N/A | B5: =COUNTIF(J:J,"=N/A") -> 0
A6: 项目名称：XXX | C6: 版本: | E6: 编制: | G6: 测试人员: | I6: 测试日期:
A7: 用例序号 | B7: 所属模块 | C7: 相关需求 | D7: 用例标题 | E7: 前置条件 | F7: 步骤 | G7: 预期 | H7: 优先级 | I7: 用例执行方式 | J7: 用例执行结果 | K7: DTM缺陷号
A8: 1 | B8: 多媒体 | C8: FID-01.01 | D8: 待机取消常显 | E8: 1.HU和IP网络通讯互联成功 2.BAT IGN ACC均已上电 3.网络仿真工具与HU IP正常通信 4.HU任意播放源 5.IP 端常显多媒体信息 | F8: 1.HU进入待机 | G8: 1.IP 端常显多媒体信息取消显示 | H8: 1 | I8: 台架
A9: 2 | B9: 多媒体 | C9: FID-01.01 | D9: 关机状态MODE无效 | E9: 1.HU和IP网络通讯互联成功 2.BAT IGN ACC均已上电 3.网络仿真工具与HU IP正常通信 4.HU任意播放源 5.IP 端常显多媒体信息 | F9: 1.HU关机 2.操作mode按键 | G9: 1.无响应 | H9: 1 | I9: 台架
A10: 3 | B10: 多媒体 | C10: FID-01.01.01 | D10: 呼出媒体源菜单 | E10: 1.HU和IP网络通讯互联成功 2.BAT IGN ACC均已上电 3.网络仿真工具与HU IP正常通信 4.HU任意播放源 | F10: 1.短按方控 mode 键（♫） | G10: 1.HU 不动作 2.IP 呼出媒体源菜单 | H10: 1 | I10: 台架
A11: 4 | B11: 多媒体 | C11: FID-01.01.01 | D11: 播放源切换顺序 | E11: 1.HU和IP网络通讯互联成功 2.BAT IGN ACC均已上电 3.网络仿真工具与HU IP正常通信 4.本地音乐有可播放文件，USB里有可播放文件且已连接，蓝牙音乐已连接有可播放蓝牙音乐 | F11: 1.短按方控 mode 键（♫） 2.再次短按方控 mode 键（♫） | G11: 1.1. IP及HU多媒体信息按“蓝牙音乐、在线音乐、本地音乐、 广播电台、在线节目”顺序循环切换 | H11: 1 | I11: 台架
A12: 5 | B12: 多媒体 | C12: FID-01.01.01.01 | D12: 常亮状态 | E12: 1.HU和IP网络通讯互联成功 2.BAT IGN ACC均已上电 3.网络仿真工具与HU IP正常通信 4.本地音乐有可播放文件，USB里有可播放文件且已连接，蓝牙音乐已连接有可播放蓝牙音乐 5.HU 发送给 IP 的[type=0x01] [subtype=0x01]HU 状态信息中 sourceUSB=1、sourceHDD=1、 sourceBT=1 | F12: 1.短按方控 mode 键（♫） | G12: 1.：广播电台图标保持常亮；在线 节目、在线音乐，USB音乐，本地音乐，蓝牙音乐图标点亮 | H12: 1 | I12: 台架
A13: 6 | B13: 多媒体 | C13: FID-01.01.01.01 | D13: 置灰状态 | E13: 1.HU和IP网络通讯互联成功 2.BAT IGN ACC均已上电 3.网络仿真工具与HU IP正常通信 4.本地音乐无可播放文件，USB里无可播放文件且已连接，蓝牙音乐已连接无可播放蓝牙音乐 5.HU 发送给 IP 的[type=0x01] [subtype=0x01]HU 状态信息中 sourceUSB=0、sourceHDD=0、 sourceBT=10 | F13: 1.短按方控 mode 键（♫） | G13: 1.：广播电台图标保持常亮；在线 节目、在线音乐；USB音乐图标置灰，本地音乐图标置灰，蓝牙音乐图标置灰保持常亮 | H13: 1 | I13: 台架
A14: 7 | B14: 多媒体 | C14: FID-01.01.01.01 | D14: 置灰状态 | E14: 1.HU和IP网络通讯互联成功 2.BAT IGN ACC均已上电 3.网络仿真工具与HU IP正常通信 4.本地音乐无可播放文件，USB未连接，蓝牙音乐未连接 5.5.HU 发送给 IP 的[type=0x01] [subtype=0x01]HU 状态信息中 sourceUSB=0、sourceHDD=0、 sourceBT=10 | F14: 1.短按方控 mode 键（♫） | G14: 1.：广播电台图标保持常亮；在线 节目、在线音乐；USB音乐图标置灰，本地音乐图标置灰，蓝牙音乐图标置灰保持常亮 | H14: 1 | I14: 台架
A15: 8 | B15: 多媒体 | C15: FID-01.01.01.02 | D15: 默认进入当前播放的媒体源图标 | E15: 1.HU和IP网络通讯互联成功 2.BAT IGN ACC均已上电 3.网络仿真工具与HU IP正常通信 4.HU当前播放源为蓝牙音乐 | F15: 1.短按方控 mode 键（♫） | G15: 1.IP进入当前蓝牙音乐的媒体源图标 2.仪表根据HU发送给IP的[type=0x01] [subtype=0x01]HU 状态信息中sourceStatus=47 | H15: 1 | I15: 台架
A16: 9 | B16: 多媒体 | C16: FID-01.01.01.02 | D16: 默认进入当前播放的媒体源图标 | E16: 1.HU和IP网络通讯互联成功 2.BAT IGN ACC均已上电 3.网络仿真工具与HU IP正常通信 4.HU当前播放源为在线音乐 | F16: 1.短按方控 mode 键（♫） | G16: 1.IP进入当前在线音乐的媒体源图标 2.仪表根据HU发送给IP的[type=0x01] [subtype=0x01]HU 状态信息中sourceStatus=13 | H16: 1 | I16: 台架
A17: 10 | B17: 多媒体 | C17: FID-01.01.01.02 | D17: 默认进入当前播放的媒体源图标 | E17: 1.HU和IP网络通讯互联成功 2.BAT IGN ACC均已上电 3.网络仿真工具与HU IP正常通信 4.HU当前播放源为USB音乐 | F17: 1.短按方控 mode 键（♫） | G17: 1.IP进入当前USB音乐的媒体源图标 2.仪表根据HU发送给IP的[type=0x01] [subtype=0x01]HU 状态信息中sourceStatus=11 | H17: 1 | I17: 台架
A18: 11 | B18: 多媒体 | C18: FID-01.01.01.02 | D18: 默认进入当前播放的媒体源图标 | E18: 1.HU和IP网络通讯互联成功 2.BAT IGN ACC均已上电 3.网络仿真工具与HU IP正常通信 4.HU当前播放源为本地音乐 | F18: 1.短按方控 mode 键（♫） | G18: 1.IP进入当前本地音乐的媒体源图标 2.仪表根据HU发送给IP的[type=0x01] [subtype=0x01]HU 状态信息中sourceStatus=10 | H18: 1 | I18: 台架
A19: 12 | B19: 多媒体 | C19: FID-01.01.01.02 | D19: 默认进入当前播放的媒体源图标 | E19: 1.HU和IP网络通讯互联成功 2.BAT IGN ACC均已上电 3.网络仿真工具与HU IP正常通信 4.HU当前播放源为广播电台 | F19: 1.短按方控 mode 键（♫） | G19: 1.IP进入当前广播电台的媒体源图标 2.仪表根据HU发送给IP的[type=0x01] [subtype=0x01]HU 状态信息中sourceStatus=1 | H19: 1 | I19: 台架
... A203: 196 | B203: 电话 | C203: FID-02.02.02 | D203: 来电 | E203: 1.HU和IP网络通讯互联成功 2.BAT IGN ACC均已上电 3.网络仿真工具与HU IP正常通信 4.来电中界面 | F203: 1. 左右键切换至挂断 | G203: 1.仪表和HU同步挂断 2.接听电话：挂断电话：[type:0x12] [Subtype:0x07]HU_control_t：cmd=1 ，电话状态：[type=0x01] [subtype=0x01]BTPhoneStatus | H203: 1 | I203: 台架

Sheet 系统设置
A1: 总用例 | B1: 192 | C1: XXX零部件测试系统设置用例
A2: passed | B2: =COUNTIF(J:J,"=passed") -> 0
A3: failed | B3: =COUNTIF(J:J,"=failed") -> 0
A4: blocked | B4: =COUNTIF(J:J,"=blocked") -> 0
A5: N/A | B5: =COUNTIF(J:J,"=N/A") -> 0
A6: 项目名称：XXX | C6: 版本: | E6: 编制: | G6: 测试人员: | I6: 测试日期:
A7: 用例序号 | B7: 所属模块 | C7: 相关需求 | D7: 用例标题 | E7: 前置条件 | F7: 步骤 | G7: 预期 | H7: 优先级 | I7: 用例执行方式 | J7: 用例执行结果 | K7: DTM缺陷号
A8: 1 | B8: 系统设置 | C8: I215.01.01.00-语言设置 | D8: F-系统设置下语言设置界面显示（非海外机型） | E8: 1.之前未进入到语言设置中进行设置语言； 2.进入系统设置→语言设置 | F8: 1. 查看界面显示情况 | G8: 1.界面显示符合UI设置，默认语言为中文； | H8: 1 | I8: 台架
A9: 2 | B9: 系统设置 | C9: I215.01.01.00-语言设置 | D9: F-系统设置下语言设置界面显示（海外机型） | E9: 1.之前未进入到语言设置中进行设置语言； 2.进入系统设置→语言设置 | F9: 1. 查看界面显示情况 | G9: 1.界面显示符合UI设置，默认语言看实际机型要求； | H9: 1 | I9: 台架
A10: 3 | B10: 系统设置 | C10: I215.01.01.00-语言设置 | D10: S-系统设置下语言切换功能（非海外机型） | E10: 进入系统设置→语言设置 | F10: 1. 界面语言切换，从中文切换到英文 2. 回到主页面； 3. 检查电话、文件管理、车辆设置3个APP界面语言显示； | G10: 1. 语言可以切换 2. 主页面显示语言切换成功，英文翻译无明显异常 3. 进入APP后一级菜单语言切换成功 | H10: 1 | I10: 台架
A11: 4 | B11: 系统设置 | C11: I215.01.01.00-语言设置 | D11: S-系统设置下语言切换功能（非海外机型） | E11: 进入系统设置→语言设置 | F11: 1. 界面语言切换，从英文切换到中文 2. 回到主页面； 3. 检查电话、文件管理、车辆设置3个APP界面语言显示； | G11: 1. 语言可以切换 2. 主页面显示语言切换成功 3. 进入APP后一级菜单语言切换成功 | H11: 1 | I11: 台架
A12: 5 | B12: 系统设置 | C12: I215.01.01.00-语言设置 | D12: S-系统设置下语言切换功能（海外机型） | E12: 进入系统设置→语言设置 | F12: 1. 界面语言切换，从英文切换到中文 2. 回到主页面； 3. 检查电话、文件管理、车辆设置3个APP界面语言显示； | G12: 1. 语言可以切换 2. 主页面显示语言切换成功 3. 进入APP后一级菜单语言切换成功 | H12: 1 | I12: 台架
A13: 6 | B13: 系统设置 | C13: I215.01.01.00-语言设置 | D13: S-系统设置下语言切换功能（海外机型） | E13: 进入系统设置→语言设置 | F13: 1. 界面语言切换，从英文切换到阿拉伯文 2. 回到主页面； 3. 检查电话、文件管理、车辆设置3个APP界面语言显示； | G13: 1. 语言可以切换 2. 主页面显示语言切换成功 3. 进入APP后一级菜单语言切换成功 | H13: 1 | I13: 台架
A14: 7 | B14: 系统设置 | C14: I215.01.01.00-语言设置 | D14: S-系统设置下语言切换功能（海外机型） | E14: 进入系统设置→语言设置 | F14: 1. 界面语言切换，从英文切换到俄文 2. 回到主页面； 3. 检查电话、文件管理、车辆设置3个APP界面语言显示； | G14: 1. 语言可以切换 2. 主页面显示语言切换成功 3. 进入APP后一级菜单语言切换成功 | H14: 1 | I14: 台架
A15: 8 | B15: 系统设置 | C15: I215.01.01.00-语言设置 | D15: S-系统设置下语言切换功能（海外机型） | E15: 进入系统设置→语言设置 | F15: 1. 界面语言切换，从英文切换到西班牙文 2. 回到主页面； 3. 检查电话、文件管理、车辆设置3个APP界面语言显示； | G15: 1. 语言可以切换 2. 主页面显示语言切换成功 3. 进入APP后一级菜单语言切换成功 | H15: 1 | I15: 台架
A16: 9 | B16: 系统设置 | C16: I215.01.01.00-语言设置 | D16: S-系统设置下语言切换功能（海外机型） | E16: 进入系统设置→语言设置 | F16: 1. 界面语言切换，从英文切换到葡萄牙文 2. 回到主页面； 3. 检查电话、文件管理、车辆设置3个APP界面语言显示； | G16: 1. 语言可以切换 2. 主页面显示语言切换成功 3. 进入APP后一级菜单语言切换成功 | H16: 1 | I16: 台架
A17: 10 | B17: 系统设置 | C17: I215.01.01.00-语言设置 | D17: S-系统设置仪表语言切换功能 | E17: 1.支持HU与仪表同步机型 2.有仪表 | F17: 1.HU设置系统语言为英文，查看仪表语言； 2.HU设置系统语言切换为中文，查看仪表语言； | G17: 1-2.仪表语言显示同步切换成功，英文翻译无明显异常 | H17: 2 | I17: 台架
A18: 11 | B18: 系统设置 | C18: I215.01.01.00-语言设置 | D18: S-系统设置仪表语言切换功能(CAN仿真) | E18: 无仪表需要仿真测试 1.支持HU与仪表同步机型 2.车机连接kvaser进行CAN仿真 | F18: 1.HU设置系统语言为英文，查看仪表语言； 2.HU设置系统语言切换为中文，查看仪表语言； | G18: 1.CAN仿真软件检查HU发出信号：ID=38E，HU_LanguageSync=0x1，cycle=100ms； 2.CAN仿真软件检查HU发出信号：ID=38E，HU_LanguageSync=0x0，cycle=100ms； | H18: 2 | I18: 仿真
A19: 12 | B19: 系统设置 | C19: I215.01.02.00-时间格式 | D19: F-系统设置下时间格式界面显示 | E19: 1.之前未进入到时间格式中进行设置选择； 2.进入系统设置→时间格式 | F19: 1.查看界面显示情况 2.切换系统语言设置 | G19: 1.默认显示为24小时制 2.时间格式显示无变化 | H19: 4 | I19: 台架
... A199: 192 | B199: 系统设置 | C199: I215系统设置需求规格说明书-V2.2-压力测试 | D199: F-蓝牙开关压力测试 | E199: 1.已连接蓝牙手机，车机端联系人同步开关打开； | F199: 1.播放蓝牙音乐，进入系统设置，反复切换蓝牙开关100次，每个间隔10s； 2.主叫呼出蓝牙电话，接听过程中关闭蓝牙开关，隔10s后开启蓝牙开关，蓝牙开关切换100次，单次蓝牙电话时长要求≥10分钟； | G199: 1.蓝牙断开后，音乐声音不从车机输出，手机是否继续播放取决于手机的逻辑(可以播放即可)，再次连接蓝牙前手机播放音乐； 2.电话中，蓝牙关闭时通话声回到手机输出，蓝牙连接时通话声回到车机蓝牙输出，通话声音切换准确，无明显音质问题； | H199: 3 | I199: 台架

Sheet 智能提示
A1: 总用例 | B1: 57 | C1: XXX零部件测试智能提示用例
A2: passed | B2: =COUNTIF(J:J,"=passed") -> 0
A3: failed | B3: =COUNTIF(J:J,"=failed") -> 0
A4: blocked | B4: =COUNTIF(J:J,"=blocked") -> 0
A5: N/A | B5: =COUNTIF(J:J,"=N/A") -> 0
A6: 项目名称：XXX | C6: 版本: | E6: 编制: | G6: 测试人员: | I6: 测试日期:
A7: 用例序号 | B7: 所属模块 | C7: 相关需求 | D7: 用例标题 | E7: 前置条件 | F7: 步骤 | G7: 预期 | H7: 优先级 | I7: 用例执行方式 | J7: 用例执行结果 | K7: DTM缺陷号
